Workbook

Sheet 前三
A1: 层位 | D1: 风化带 | G1: 取样编号 | J1: 风化带文字坐标
A3: 深度 | B3: 坐标 | D3: 深度 | E3: 坐标 | G3: 深度 | H3: 坐标 | J3: 标注 | K3: 坐标
B4: {=-INDEX(A:A,ROUNDUP(ROW(A8)/2,0))} -> 0 | C4: 8 | E4: {=-INDEX(D:D,ROUNDUP(ROW(D8)/2,0))} -> 0 | F4: 16 | H4: {=-INDEX(G:G,ROUNDUP(ROW(G8)/2,0))} -> 0 | I4: 18 | J4: =D5 -> 1.1 | K4: =E6 -> -1.1 | L4: =F6-IF(LEN(TEXT(J4,"0"))=1,0.5,IF(LEN(TEXT(J4,"0"))=2,0.61,0.81)) -> 13.5
A5: 1.73 | B5: {=-INDEX(A:A,ROUNDUP(ROW(A9)/2,0))} -> -1.73 | C5: 8 | E5: {=-INDEX(D:D,ROUNDUP(ROW(D9)/2,0))} -> -1.1 | F5: 16 | H5: {=-INDEX(G:G,ROUNDUP(ROW(G9)/2,0))} -> 0 | I5: 18 | K5: =K6-(K6-K4+0.3)*0.3 -> -1.75 | L5: 13.69
A6: 8.84 | B6: {=-INDEX(A:A,ROUNDUP(ROW(A10)/2,0))} -> -1.73 | C6: 6 | E6: {=-INDEX(D:D,ROUNDUP(ROW(D10)/2,0))} -> -1.1 | F6: 14 | H6: {=-INDEX(G:G,ROUNDUP(ROW(G10)/2,0))} -> 0 | I6: 16 | J6: 强风化 | K6: =IF(K8<K4,(K8+K4)/2-0.3,0) -> -1.9 | L6: 13.11
A7: 69 | B7: {=-INDEX(A:A,ROUNDUP(ROW(A11)/2,0))} -> -8.84 | C7: 6 | E7: {=-INDEX(D:D,ROUNDUP(ROW(D11)/2,0))} -> -2.1 | F7: 14 | H7: {=-INDEX(G:G,ROUNDUP(ROW(G11)/2,0))} -> 0 | I7: 16 | K7: =K6+(K8-0.3-K6)*0.3 -> -2.05 | L7: 13.69
A8: 71.69 | B8: {=-INDEX(A:A,ROUNDUP(ROW(A12)/2,0))} -> -8.84 | C8: 8 | E8: {=-INDEX(D:D,ROUNDUP(ROW(D12)/2,0))} -> -2.1 | F8: 16 | H8: {=-INDEX(G:G,ROUNDUP(ROW(G12)/2,0))} -> 0 | I8: 18 | J8: =D6 -> 2.1 | K8: =E7 -> -2.1 | L8: =F7-IF(LEN(TEXT(J8,"0"))=1,0.5,IF(LEN(TEXT(J8,"0"))=2,0.61,0.81)) -> 13.5
A9: 105 | B9: {=-INDEX(A:A,ROUNDUP(ROW(A13)/2,0))} -> -69 | C9: 8 | E9: {=-INDEX(D:D,ROUNDUP(ROW(D13)/2,0))} -> -37.37 | F9: 16 | H9: {=-INDEX(G:G,ROUNDUP(ROW(G13)/2,0))} -> 0 | I9: 18 | K9: =K10-(K10-K8+0.3)*0.3 -> -14.7445 | L9: 13.69
A10: 129.95 | B10: {=-INDEX(A:A,ROUNDUP(ROW(A14)/2,0))} -> -69 | C10: 6 | E10: {=-INDEX(D:D,ROUNDUP(ROW(D14)/2,0))} -> -37.37 | F10: 14 | H10: {=-INDEX(G:G,ROUNDUP(ROW(G14)/2,0))} -> 0 | I10: 16 | J10: 中风化 | K10: =IF(K12<K8,(K12+K8)/2-0.3,0) -> -20.035 | L10: 13.11
A11: 137.69 | B11: {=-INDEX(A:A,ROUNDUP(ROW(A15)/2,0))} -> -71.69 | C11: 6 | E11: {=-INDEX(D:D,ROUNDUP(ROW(D15)/2,0))} -> 0 | F11: 14 | H11: {=-INDEX(G:G,ROUNDUP(ROW(G15)/2,0))} -> 0 | I11: 16 | K11: =K10+(K12-0.3-K10)*0.3 -> -25.3255 | L11: 13.69
A12: 140.82 | B12: {=-INDEX(A:A,ROUNDUP(ROW(A16)/2,0))} -> -71.69 | C12: 8 | E12: {=-INDEX(D:D,ROUNDUP(ROW(D16)/2,0))} -> 0 | F12: 16 | H12: {=-INDEX(G:G,ROUNDUP(ROW(G16)/2,0))} -> 0 | I12: 18 | J12: =D7 -> 37.37 | K12: =E10 -> -37.37 | L12: =F10-IF(LEN(TEXT(J12,"0"))=1,0.5,IF(LEN(TEXT(J12,"0"))=2,0.61,0.81)) -> 13.39
A13: 145.23 | B13: {=-INDEX(A:A,ROUNDUP(ROW(A17)/2,0))} -> -105 | C13: 8 | E13: {=-INDEX(D:D,ROUNDUP(ROW(D17)/2,0))} -> 0 | F13: 16 | H13: {=-INDEX(G:G,ROUNDUP(ROW(G17)/2,0))} -> 0 | I13: 18 | K13: =K14-(K14-K12+0.3)*0.3 -> -261.8555 | L13: 13.69
A14: 180.37 | B14: {=-INDEX(A:A,ROUNDUP(ROW(A18)/2,0))} -> -105 | C14: 6 | E14: {=-INDEX(D:D,ROUNDUP(ROW(D18)/2,0))} -> 0 | F14: 14 | H14: {=-INDEX(G:G,ROUNDUP(ROW(G18)/2,0))} -> 0 | I14: 16 | J14: 微风化 | K14: =(-K17+K12)/2-0.3 -> -357.935 | L14: 13.11
A15: 187.35 | B15: {=-INDEX(A:A,ROUNDUP(ROW(A19)/2,0))} -> -129.95 | C15: 6 | E15: {=-INDEX(D:D,ROUNDUP(ROW(D19)/2,0))} -> 0 | F15: 14 | H15: {=-INDEX(G:G,ROUNDUP(ROW(G19)/2,0))} -> 0 | I15: 16 | K15: =K14+(-K17-0.3-K14)*0.3 -> -454.0145 | L15: 13.69
A16: 189.92 | B16: {=-INDEX(A:A,ROUNDUP(ROW(A20)/2,0))} -> -129.95 | C16: 8 | E16: {=-INDEX(D:D,ROUNDUP(ROW(D20)/2,0))} -> 0 | F16: 16 | H16: {=-INDEX(G:G,ROUNDUP(ROW(G20)/2,0))} -> 0 | I16: 18
A17: 193.94 | B17: {=-INDEX(A:A,ROUNDUP(ROW(A21)/2,0))} -> -137.69 | C17: 8 | E17: {=-INDEX(D:D,ROUNDUP(ROW(D21)/2,0))} -> 0 | F17: 16 | H17: {=-INDEX(G:G,ROUNDUP(ROW(G21)/2,0))} -> 0 | I17: 18 | J17: 孔深输入：
A18: 196.59 | B18: {=-INDEX(A:A,ROUNDUP(ROW(A22)/2,0))} -> -137.69 | C18: 6 | E18: {=-INDEX(D:D,ROUNDUP(ROW(D22)/2,0))} -> 0 | F18: 14 | H18: {=-INDEX(G:G,ROUNDUP(ROW(G22)/2,0))} -> 0 | I18: 16
A19: 211.19 | B19: {=-INDEX(A:A,ROUNDUP(ROW(A23)/2,0))} -> -140.82 | C19: 6 | E19: {=-INDEX(D:D,ROUNDUP(ROW(D23)/2,0))} -> 0 | F19: 14 | H19: {=-INDEX(G:G,ROUNDUP(ROW(G23)/2,0))} -> 0 | I19: 16
A20: 218.14 | B20: {=-INDEX(A:A,ROUNDUP(ROW(A24)/2,0))} -> -140.82 | C20: 8 | E20: {=-INDEX(D:D,ROUNDUP(ROW(D24)/2,0))} -> 0 | F20: 16 | H20: {=-INDEX(G:G,ROUNDUP(ROW(G24)/2,0))} -> 0 | I20: 18
A21: 223.68 | B21: {=-INDEX(A:A,ROUNDUP(ROW(A25)/2,0))} -> -145.23 | C21: 8 | E21: {=-INDEX(D:D,ROUNDUP(ROW(D25)/2,0))} -> 0 | F21: 16 | H21: {=-INDEX(G:G,ROUNDUP(ROW(G25)/2,0))} -> 0 | I21: 18
A22: 228.03 | B22: {=-INDEX(A:A,ROUNDUP(ROW(A26)/2,0))} -> -145.23 | C22: 6 | E22: {=-INDEX(D:D,ROUNDUP(ROW(D26)/2,0))} -> 0 | F22: 14 | H22: {=-INDEX(G:G,ROUNDUP(ROW(G26)/2,0))} -> 0 | I22: 16
A23: 265.05 | B23: {=-INDEX(A:A,ROUNDUP(ROW(A27)/2,0))} -> -180.37 | C23: 6 | E23: {=-INDEX(D:D,ROUNDUP(ROW(D27)/2,0))} -> 0 | F23: 14 | H23: {=-INDEX(G:G,ROUNDUP(ROW(G27)/2,0))} -> 0 | I23: 16
A24: 280.77 | B24: {=-INDEX(A:A,ROUNDUP(ROW(A28)/2,0))} -> -180.37 | C24: 8 | E24: {=-INDEX(D:D,ROUNDUP(ROW(D28)/2,0))} -> 0 | F24: 16 | H24: {=-INDEX(G:G,ROUNDUP(ROW(G28)/2,0))} -> 0 | I24: 18
A25: 304.2 | B25: {=-INDEX(A:A,ROUNDUP(ROW(A29)/2,0))} -> -187.35 | C25: 8 | E25: {=-INDEX(D:D,ROUNDUP(ROW(D29)/2,0))} -> 0 | F25: 16 | H25: {=-INDEX(G:G,ROUNDUP(ROW(G29)/2,0))} -> 0 | I25: 18
A26: 315.45 | B26: {=-INDEX(A:A,ROUNDUP(ROW(A30)/2,0))} -> -187.35 | C26: 6 | E26: {=-INDEX(D:D,ROUNDUP(ROW(D30)/2,0))} -> 0 | F26: 14 | H26: {=-INDEX(G:G,ROUNDUP(ROW(G30)/2,0))} -> 0 | I26: 16
A27: 343.46 | B27: {=-INDEX(A:A,ROUNDUP(ROW(A31)/2,0))} -> -189.92 | C27: 6 | E27: {=-INDEX(D:D,ROUNDUP(ROW(D31)/2,0))} -> 0 | F27: 14 | H27: {=-INDEX(G:G,ROUNDUP(ROW(G31)/2,0))} -> 0 | I27: 16
A28: 347.46 | B28: {=-INDEX(A:A,ROUNDUP(ROW(A32)/2,0))} -> -189.92 | C28: 8
A29: 368.68 | B29: {=-INDEX(A:A,ROUNDUP(ROW(A33)/2,0))} -> -193.94 | C29: 8
A30: 374.06 | B30: {=-INDEX(A:A,ROUNDUP(ROW(A34)/2,0))} -> -193.94 | C30: 6
A31: 386.97 | B31: {=-INDEX(A:A,ROUNDUP(ROW(A35)/2,0))} -> -196.59 | C31: 6
A32: 427.42 | B32: {=-INDEX(A:A,ROUNDUP(ROW(A36)/2,0))} -> -196.59 | C32: 8
A33: 431.46 | B33: {=-INDEX(A:A,ROUNDUP(ROW(A37)/2,0))} -> -211.19 | C33: 8
A34: 433.79 | B34: {=-INDEX(A:A,ROUNDUP(ROW(A38)/2,0))} -> -211.19 | C34: 6
A35: 453.52 | B35: {=-INDEX(A:A,ROUNDUP(ROW(A39)/2,0))} -> -218.14 | C35: 6
A36: 515.59 | B36: {=-INDEX(A:A,ROUNDUP(ROW(A40)/2,0))} -> -218.14 | C36: 8
A37: 518.7 | B37: {=-INDEX(A:A,ROUNDUP(ROW(A41)/2,0))} -> -223.68 | C37: 8
A38: 525.1 | B38: {=-INDEX(A:A,ROUNDUP(ROW(A42)/2,0))} -> -223.68 | C38: 6
A39: 540.2 | B39: {=-INDEX(A:A,ROUNDUP(ROW(A43)/2,0))} -> -228.03 | C39: 6
... A43: 590.2 | B43: {=-INDEX(A:A,ROUNDUP(ROW(A47)/2,0))} -> -280.77 | C43: 6
B44: {=-INDEX(A:A,ROUNDUP(ROW(A48)/2,0))} -> -280.77 | C44: 8
...

Sheet 采取率投图
D1: x1 | E1: y1 | F1: x2 | G1: y2 | J1: {=IF(ROW(J1)<=COUNTA(D:D)*2,IF(MOD(ROW(J1),2)=1,INDEX(D:D,(ROW(J1)+1)/2),INDEX(F:F,ROW(J1)/2)),"")} -> x1 | K1: {=IF(ROW(K1)<=COUNTA(E:E)*2,IF(MOD(ROW(K1),2)=1,INDEX(E:E,(ROW(K1)+1)/2),INDEX(G:G,ROW(K1)/2)),"")} -> y1
D2: =0 -> 0 | E2: =41+(B2/100)*4 -> 44.789474 | F2: =0-A2 -> -1.9 | G2: =41+(B2/100)*4 -> 44.789474 | J2: {=IF(ROW(J2)<=COUNTA(D:D)*2,IF(MOD(ROW(J2),2)=1,INDEX(D:D,(ROW(J2)+1)/2),INDEX(F:F,ROW(J2)/2)),"")} -> x2 | K2: {=IF(ROW(K2)<=COUNTA(E:E)*2,IF(MOD(ROW(K2),2)=1,INDEX(E:E,(ROW(K2)+1)/2),INDEX(G:G,ROW(K2)/2)),"")} -> y2
D3: =0-A2 -> -1.9 | E3: =41+(B3/100)*4 -> 44.98 | F3: =0-A3 -> -3.9 | G3: =41+(B3/100)*4 -> 44.98 | J3: {=IF(ROW(J3)<=COUNTA(D:D)*2,IF(MOD(ROW(J3),2)=1,INDEX(D:D,(ROW(J3)+1)/2),INDEX(F:F,ROW(J3)/2)),"")} -> 0 | K3: {=IF(ROW(K3)<=COUNTA(E:E)*2,IF(MOD(ROW(K3),2)=1,INDEX(E:E,(ROW(K3)+1)/2),INDEX(G:G,ROW(K3)/2)),"")} -> 44.789474
D4: =0-A3 -> -3.9 | E4: =41+(B4/100)*4 -> 44.88 | F4: =0-A4 -> -5.9 | G4: =41+(B4/100)*4 -> 44.88 | J4: {=IF(ROW(J4)<=COUNTA(D:D)*2,IF(MOD(ROW(J4),2)=1,INDEX(D:D,(ROW(J4)+1)/2),INDEX(F:F,ROW(J4)/2)),"")} -> -1.9 | K4: {=IF(ROW(K4)<=COUNTA(E:E)*2,IF(MOD(ROW(K4),2)=1,INDEX(E:E,(ROW(K4)+1)/2),INDEX(G:G,ROW(K4)/2)),"")} -> 44.789474
D5: =0-A4 -> -5.9 | E5: =41+(B5/100)*4 -> 44.92 | F5: =0-A5 -> -7.9 | G5: =41+(B5/100)*4 -> 44.92 | J5: {=IF(ROW(J5)<=COUNTA(D:D)*2,IF(MOD(ROW(J5),2)=1,INDEX(D:D,(ROW(J5)+1)/2),INDEX(F:F,ROW(J5)/2)),"")} -> -1.9 | K5: {=IF(ROW(K5)<=COUNTA(E:E)*2,IF(MOD(ROW(K5),2)=1,INDEX(E:E,(ROW(K5)+1)/2),INDEX(G:G,ROW(K5)/2)),"")} -> 44.98
D6: =0-A5 -> -7.9 | E6: =41+(B6/100)*4 -> 44.96 | F6: =0-A6 -> -9.9 | G6: =41+(B6/100)*4 -> 44.96 | J6: {=IF(ROW(J6)<=COUNTA(D:D)*2,IF(MOD(ROW(J6),2)=1,INDEX(D:D,(ROW(J6)+1)/2),INDEX(F:F,ROW(J6)/2)),"")} -> -3.9 | K6: {=IF(ROW(K6)<=COUNTA(E:E)*2,IF(MOD(ROW(K6),2)=1,INDEX(E:E,(ROW(K6)+1)/2),INDEX(G:G,ROW(K6)/2)),"")} -> 44.98
D7: =0-A6 -> -9.9 | E7: =41+(B7/100)*4 -> 44.94 | F7: =0-A7 -> -11.9 | G7: =41+(B7/100)*4 -> 44.94 | J7: {=IF(ROW(J7)<=COUNTA(D:D)*2,IF(MOD(ROW(J7),2)=1,INDEX(D:D,(ROW(J7)+1)/2),INDEX(F:F,ROW(J7)/2)),"")} -> -3.9 | K7: {=IF(ROW(K7)<=COUNTA(E:E)*2,IF(MOD(ROW(K7),2)=1,INDEX(E:E,(ROW(K7)+1)/2),INDEX(G:G,ROW(K7)/2)),"")} -> 44.88
D8: =0-A7 -> -11.9 | E8: =41+(B8/100)*4 -> 44.98 | F8: =0-A8 -> -13.9 | G8: =41+(B8/100)*4 -> 44.98 | J8: {=IF(ROW(J8)<=COUNTA(D:D)*2,IF(MOD(ROW(J8),2)=1,INDEX(D:D,(ROW(J8)+1)/2),INDEX(F:F,ROW(J8)/2)),"")} -> -5.9 | K8: {=IF(ROW(K8)<=COUNTA(E:E)*2,IF(MOD(ROW(K8),2)=1,INDEX(E:E,(ROW(K8)+1)/2),INDEX(G:G,ROW(K8)/2)),"")} -> 44.88
D9: =0-A8 -> -13.9 | E9: =41+(B9/100)*4 -> 44.9 | F9: =0-A9 -> -15.9 | G9: =41+(B9/100)*4 -> 44.9 | J9: {=IF(ROW(J9)<=COUNTA(D:D)*2,IF(MOD(ROW(J9),2)=1,INDEX(D:D,(ROW(J9)+1)/2),INDEX(F:F,ROW(J9)/2)),"")} -> -5.9 | K9: {=IF(ROW(K9)<=COUNTA(E:E)*2,IF(MOD(ROW(K9),2)=1,INDEX(E:E,(ROW(K9)+1)/2),INDEX(G:G,ROW(K9)/2)),"")} -> 44.92
D10: =0-A9 -> -15.9 | E10: =41+(B10/100)*4 -> 44.86 | F10: =0-A10 -> -17.9 | G10: =41+(B10/100)*4 -> 44.86 | J10: {=IF(ROW(J10)<=COUNTA(D:D)*2,IF(MOD(ROW(J10),2)=1,INDEX(D:D,(ROW(J10)+1)/2),INDEX(F:F,ROW(J10)/2)),"")} -> -7.9 | K10: {=IF(ROW(K10)<=COUNTA(E:E)*2,IF(MOD(ROW(K10),2)=1,INDEX(E:E,(ROW(K10)+1)/2),INDEX(G:G,ROW(K10)/2)),"")} -> 44.92
D11: =0-A10 -> -17.9 | E11: =41+(B11/100)*4 -> 44.88 | F11: =0-A11 -> -19.9 | G11: =41+(B11/100)*4 -> 44.88 | J11: {=IF(ROW(J11)<=COUNTA(D:D)*2,IF(MOD(ROW(J11),2)=1,INDEX(D:D,(ROW(J11)+1)/2),INDEX(F:F,ROW(J11)/2)),"")} -> -7.9 | K11: {=IF(ROW(K11)<=COUNTA(E:E)*2,IF(MOD(ROW(K11),2)=1,INDEX(E:E,(ROW(K11)+1)/2),INDEX(G:G,ROW(K11)/2)),"")} -> 44.96
D12: =0-A11 -> -19.9 | E12: =41+(B12/100)*4 -> 44.86 | F12: =0-A12 -> -21.9 | G12: =41+(B12/100)*4 -> 44.86 | J12: {=IF(ROW(J12)<=COUNTA(D:D)*2,IF(MOD(ROW(J12),2)=1,INDEX(D:D,(ROW(J12)+1)/2),INDEX(F:F,ROW(J12)/2)),"")} -> -9.9 | K12: {=IF(ROW(K12)<=COUNTA(E:E)*2,IF(MOD(ROW(K12),2)=1,INDEX(E:E,(ROW(K12)+1)/2),INDEX(G:G,ROW(K12)/2)),"")} -> 44.96
D13: =0-A12 -> -21.9 | E13: =41+(B13/100)*4 -> 44.92 | F13: =0-A13 -> -23.9 | G13: =41+(B13/100)*4 -> 44.92 | J13: {=IF(ROW(J13)<=COUNTA(D:D)*2,IF(MOD(ROW(J13),2)=1,INDEX(D:D,(ROW(J13)+1)/2),INDEX(F:F,ROW(J13)/2)),"")} -> -9.9 | K13: {=IF(ROW(K13)<=COUNTA(E:E)*2,IF(MOD(ROW(K13),2)=1,INDEX(E:E,(ROW(K13)+1)/2),INDEX(G:G,ROW(K13)/2)),"")} -> 44.94
D14: =0-A13 -> -23.9 | E14: =41+(B14/100)*4 -> 44.98 | F14: =0-A14 -> -25.9 | G14: =41+(B14/100)*4 -> 44.98 | J14: {=IF(ROW(J14)<=COUNTA(D:D)*2,IF(MOD(ROW(J14),2)=1,INDEX(D:D,(ROW(J14)+1)/2),INDEX(F:F,ROW(J14)/2)),"")} -> -11.9 | K14: {=IF(ROW(K14)<=COUNTA(E:E)*2,IF(MOD(ROW(K14),2)=1,INDEX(E:E,(ROW(K14)+1)/2),INDEX(G:G,ROW(K14)/2)),"")} -> 44.94
... D386: =0-A385 -> 0 | E386: =41+(B386/100)*4 -> 41 | F386: =0-A386 -> 0 | G386: =41+(B386/100)*4 -> 41 | J386: {=IF(ROW(J386)<=COUNTA(D:D)*2,IF(MOD(ROW(J386),2)=1,INDEX(D:D,(ROW(J386)+1)/2),INDEX(F:F,ROW(J386)/2)),"")} -> -383.9 | K386: {=IF(ROW(K386)<=COUNTA(E:E)*2,IF(MOD(ROW(K386),2)=1,INDEX(E:E,(ROW(K386)+1)/2),INDEX(G:G,ROW(K386)/2)),"")} -> 44.92
J387: {=IF(ROW(J387)<=COUNTA(D:D)*2,IF(MOD(ROW(J387),2)=1,INDEX(D:D,(ROW(J387)+1)/2),INDEX(F:F,ROW(J387)/2)),"")} -> -383.9 | K387: {=IF(ROW(K387)<=COUNTA(E:E)*2,IF(MOD(ROW(K387),2)=1,INDEX(E:E,(ROW(K387)+1)/2),INDEX(G:G,ROW(K387)/2)),"")} -> 44.92
J388: {=IF(ROW(J388)<=COUNTA(D:D)*2,IF(MOD(ROW(J388),2)=1,INDEX(D:D,(ROW(J388)+1)/2),INDEX(F:F,ROW(J388)/2)),"")} -> -385.9 | K388: {=IF(ROW(K388)<=COUNTA(E:E)*2,IF(MOD(ROW(K388),2)=1,INDEX(E:E,(ROW(K388)+1)/2),INDEX(G:G,ROW(K388)/2)),"")} -> 44.92
J389: {=IF(ROW(J389)<=COUNTA(D:D)*2,IF(MOD(ROW(J389),2)=1,INDEX(D:D,(ROW(J389)+1)/2),INDEX(F:F,ROW(J389)/2)),"")} -> -385.9 | K389: {=IF(ROW(K389)<=COUNTA(E:E)*2,IF(MOD(ROW(K389),2)=1,INDEX(E:E,(ROW(K389)+1)/2),INDEX(G:G,ROW(K389)/2)),"")} -> 44.94
J390: {=IF(ROW(J390)<=COUNTA(D:D)*2,IF(MOD(ROW(J390),2)=1,INDEX(D:D,(ROW(J390)+1)/2),INDEX(F:F,ROW(J390)/2)),"")} -> -387.9 | K390: {=IF(ROW(K390)<=COUNTA(E:E)*2,IF(MOD(ROW(K390),2)=1,INDEX(E:E,(ROW(K390)+1)/2),INDEX(G:G,ROW(K390)/2)),"")} -> 44.94
J391: {=IF(ROW(J391)<=COUNTA(D:D)*2,IF(MOD(ROW(J391),2)=1,INDEX(D:D,(ROW(J391)+1)/2),INDEX(F:F,ROW(J391)/2)),"")} -> -387.9 | K391: {=IF(ROW(K391)<=COUNTA(E:E)*2,IF(MOD(ROW(K391),2)=1,INDEX(E:E,(ROW(K391)+1)/2),INDEX(G:G,ROW(K391)/2)),"")} -> 44.9
J392: {=IF(ROW(J392)<=COUNTA(D:D)*2,IF(MOD(ROW(J392),2)=1,INDEX(D:D,(ROW(J392)+1)/2),INDEX(F:F,ROW(J392)/2)),"")} -> -389.9 | K392: {=IF(ROW(K392)<=COUNTA(E:E)*2,IF(MOD(ROW(K392),2)=1,INDEX(E:E,(ROW(K392)+1)/2),INDEX(G:G,ROW(K392)/2)),"")} -> 44.9
J393: {=IF(ROW(J393)<=COUNTA(D:D)*2,IF(MOD(ROW(J393),2)=1,INDEX(D:D,(ROW(J393)+1)/2),INDEX(F:F,ROW(J393)/2)),"")} -> -389.9 | K393: {=IF(ROW(K393)<=COUNTA(E:E)*2,IF(MOD(ROW(K393),2)=1,INDEX(E:E,(ROW(K393)+1)/2),INDEX(G:G,ROW(K393)/2)),"")} -> 44.9
J394: {=IF(ROW(J394)<=COUNTA(D:D)*2,IF(MOD(ROW(J394),2)=1,INDEX(D:D,(ROW(J394)+1)/2),INDEX(F:F,ROW(J394)/2)),"")} -> -391.9 | K394: {=IF(ROW(K394)<=COUNTA(E:E)*2,IF(MOD(ROW(K394),2)=1,INDEX(E:E,(ROW(K394)+1)/2),INDEX(G:G,ROW(K394)/2)),"")} -> 44.9
J395: {=IF(ROW(J395)<=COUNTA(D:D)*2,IF(MOD(ROW(J395),2)=1,INDEX(D:D,(ROW(J395)+1)/2),INDEX(F:F,ROW(J395)/2)),"")} -> -391.9 | K395: {=IF(ROW(K395)<=COUNTA(E:E)*2,IF(MOD(ROW(K395),2)=1,INDEX(E:E,(ROW(K395)+1)/2),INDEX(G:G,ROW(K395)/2)),"")} -> 44.86
J396: {=IF(ROW(J396)<=COUNTA(D:D)*2,IF(MOD(ROW(J396),2)=1,INDEX(D:D,(ROW(J396)+1)/2),INDEX(F:F,ROW(J396)/2)),"")} -> -393.9 | K396: {=IF(ROW(K396)<=COUNTA(E:E)*2,IF(MOD(ROW(K396),2)=1,INDEX(E:E,(ROW(K396)+1)/2),INDEX(G:G,ROW(K396)/2)),"")} -> 44.86
J397: {=IF(ROW(J397)<=COUNTA(D:D)*2,IF(MOD(ROW(J397),2)=1,INDEX(D:D,(ROW(J397)+1)/2),INDEX(F:F,ROW(J397)/2)),"")} -> -393.9 | K397: {=IF(ROW(K397)<=COUNTA(E:E)*2,IF(MOD(ROW(K397),2)=1,INDEX(E:E,(ROW(K397)+1)/2),INDEX(G:G,ROW(K397)/2)),"")} -> 44.96
J398: {=IF(ROW(J398)<=COUNTA(D:D)*2,IF(MOD(ROW(J398),2)=1,INDEX(D:D,(ROW(J398)+1)/2),INDEX(F:F,ROW(J398)/2)),"")} -> -395.9 | K398: {=IF(ROW(K398)<=COUNTA(E:E)*2,IF(MOD(ROW(K398),2)=1,INDEX(E:E,(ROW(K398)+1)/2),INDEX(G:G,ROW(K398)/2)),"")} -> 44.96
... J766: {=IF(ROW(J766)<=COUNTA(D:D)*2,IF(MOD(ROW(J766),2)=1,INDEX(D:D,(ROW(J766)+1)/2),INDEX(F:F,ROW(J766)/2)),"")} -> 0 | K766: {=IF(ROW(K766)<=COUNTA(E:E)*2,IF(MOD(ROW(K766),2)=1,INDEX(E:E,(ROW(K766)+1)/2),INDEX(G:G,ROW(K766)/2)),"")} -> 41

Sheet RQD投图
D1: x1 | E1: y1 | F1: x2 | G1: y2 | J1: {=IF(ROW(J1)<=COUNTA(D:D)*2,IF(MOD(ROW(J1),2)=1,INDEX(D:D,(ROW(J1)+1)/2),INDEX(F:F,ROW(J1)/2)),"")} -> x1 | K1: {=IF(ROW(K1)<=COUNTA(E:E)*2,IF(MOD(ROW(K1),2)=1,INDEX(E:E,(ROW(K1)+1)/2),INDEX(G:G,ROW(K1)/2)),"")} -> y1
D2: =0 | E2: =45+(B2/100)*4 -> 46.684211 | F2: =0-A2 -> -1.9 | G2: =45+(B2/100)*4 -> 46.684211 | J2: {=IF(ROW(J2)<=COUNTA(D:D)*2,IF(MOD(ROW(J2),2)=1,INDEX(D:D,(ROW(J2)+1)/2),INDEX(F:F,ROW(J2)/2)),"")} -> x2 | K2: {=IF(ROW(K2)<=COUNTA(E:E)*2,IF(MOD(ROW(K2),2)=1,INDEX(E:E,(ROW(K2)+1)/2),INDEX(G:G,ROW(K2)/2)),"")} -> y2
D3: =0-A2 -> -1.9 | E3: =45+(B3/100)*4 -> 47.7 | F3: =0-A3 -> -3.9 | G3: =45+(B3/100)*4 -> 47.7 | J3: 0 | K3: {=IF(ROW(K3)<=COUNTA(E:E)*2,IF(MOD(ROW(K3),2)=1,INDEX(E:E,(ROW(K3)+1)/2),INDEX(G:G,ROW(K3)/2)),"")} -> 46.684211
D4: =0-A3 -> -3.9 | E4: =45+(B4/100)*4 -> 47.94 | F4: =0-A4 -> -5.9 | G4: =45+(B4/100)*4 -> 47.94 | J4: {=IF(ROW(J4)<=COUNTA(D:D)*2,IF(MOD(ROW(J4),2)=1,INDEX(D:D,(ROW(J4)+1)/2),INDEX(F:F,ROW(J4)/2)),"")} -> -1.9 | K4: {=IF(ROW(K4)<=COUNTA(E:E)*2,IF(MOD(ROW(K4),2)=1,INDEX(E:E,(ROW(K4)+1)/2),INDEX(G:G,ROW(K4)/2)),"")} -> 46.684211
D5: =0-A4 -> -5.9 | E5: =45+(B5/100)*4 -> 46.94 | F5: =0-A5 -> -7.9 | G5: =45+(B5/100)*4 -> 46.94 | J5: {=IF(ROW(J5)<=COUNTA(D:D)*2,IF(MOD(ROW(J5),2)=1,INDEX(D:D,(ROW(J5)+1)/2),INDEX(F:F,ROW(J5)/2)),"")} -> -1.9 | K5: {=IF(ROW(K5)<=COUNTA(E:E)*2,IF(MOD(ROW(K5),2)=1,INDEX(E:E,(ROW(K5)+1)/2),INDEX(G:G,ROW(K5)/2)),"")} -> 47.7
D6: =0-A5 -> -7.9 | E6: =45+(B6/100)*4 -> 45.72 | F6: =0-A6 -> -9.9 | G6: =45+(B6/100)*4 -> 45.72 | J6: {=IF(ROW(J6)<=COUNTA(D:D)*2,IF(MOD(ROW(J6),2)=1,INDEX(D:D,(ROW(J6)+1)/2),INDEX(F:F,ROW(J6)/2)),"")} -> -3.9 | K6: {=IF(ROW(K6)<=COUNTA(E:E)*2,IF(MOD(ROW(K6),2)=1,INDEX(E:E,(ROW(K6)+1)/2),INDEX(G:G,ROW(K6)/2)),"")} -> 47.7
D7: =0-A6 -> -9.9 | E7: =45+(B7/100)*4 -> 45.88 | F7: =0-A7 -> -11.9 | G7: =45+(B7/100)*4 -> 45.88 | J7: {=IF(ROW(J7)<=COUNTA(D:D)*2,IF(MOD(ROW(J7),2)=1,INDEX(D:D,(ROW(J7)+1)/2),INDEX(F:F,ROW(J7)/2)),"")} -> -3.9 | K7: {=IF(ROW(K7)<=COUNTA(E:E)*2,IF(MOD(ROW(K7),2)=1,INDEX(E:E,(ROW(K7)+1)/2),INDEX(G:G,ROW(K7)/2)),"")} -> 47.94
D8: =0-A7 -> -11.9 | E8: =45+(B8/100)*4 -> 46.46 | F8: =0-A8 -> -13.9 | G8: =45+(B8/100)*4 -> 46.46 | J8: {=IF(ROW(J8)<=COUNTA(D:D)*2,IF(MOD(ROW(J8),2)=1,INDEX(D:D,(ROW(J8)+1)/2),INDEX(F:F,ROW(J8)/2)),"")} -> -5.9 | K8: {=IF(ROW(K8)<=COUNTA(E:E)*2,IF(MOD(ROW(K8),2)=1,INDEX(E:E,(ROW(K8)+1)/2),INDEX(G:G,ROW(K8)/2)),"")} -> 47.94
D9: =0-A8 -> -13.9 | E9: =45+(B9/100)*4 -> 47.62 | F9: =0-A9 -> -15.9 | G9: =45+(B9/100)*4 -> 47.62 | J9: {=IF(ROW(J9)<=COUNTA(D:D)*2,IF(MOD(ROW(J9),2)=1,INDEX(D:D,(ROW(J9)+1)/2),INDEX(F:F,ROW(J9)/2)),"")} -> -5.9 | K9: {=IF(ROW(K9)<=COUNTA(E:E)*2,IF(MOD(ROW(K9),2)=1,INDEX(E:E,(ROW(K9)+1)/2),INDEX(G:G,ROW(K9)/2)),"")} -> 46.94
D10: =0-A9 -> -15.9 | E10: =45+(B10/100)*4 -> 47.64 | F10: =0-A10 -> -17.9 | G10: =45+(B10/100)*4 -> 47.64 | J10: {=IF(ROW(J10)<=COUNTA(D:D)*2,IF(MOD(ROW(J10),2)=1,INDEX(D:D,(ROW(J10)+1)/2),INDEX(F:F,ROW(J10)/2)),"")} -> -7.9 | K10: {=IF(ROW(K10)<=COUNTA(E:E)*2,IF(MOD(ROW(K10),2)=1,INDEX(E:E,(ROW(K10)+1)/2),INDEX(G:G,ROW(K10)/2)),"")} -> 46.94
D11: =0-A10 -> -17.9 | E11: =45+(B11/100)*4 -> 47.56 | F11: =0-A11 -> -19.9 | G11: =45+(B11/100)*4 -> 47.56 | J11: {=IF(ROW(J11)<=COUNTA(D:D)*2,IF(MOD(ROW(J11),2)=1,INDEX(D:D,(ROW(J11)+1)/2),INDEX(F:F,ROW(J11)/2)),"")} -> -7.9 | K11: {=IF(ROW(K11)<=COUNTA(E:E)*2,IF(MOD(ROW(K11),2)=1,INDEX(E:E,(ROW(K11)+1)/2),INDEX(G:G,ROW(K11)/2)),"")} -> 45.72
D12: =0-A11 -> -19.9 | E12: =45+(B12/100)*4 -> 48.08 | F12: =0-A12 -> -21.9 | G12: =45+(B12/100)*4 -> 48.08 | J12: {=IF(ROW(J12)<=COUNTA(D:D)*2,IF(MOD(ROW(J12),2)=1,INDEX(D:D,(ROW(J12)+1)/2),INDEX(F:F,ROW(J12)/2)),"")} -> -9.9 | K12: {=IF(ROW(K12)<=COUNTA(E:E)*2,IF(MOD(ROW(K12),2)=1,INDEX(E:E,(ROW(K12)+1)/2),INDEX(G:G,ROW(K12)/2)),"")} -> 45.72
D13: =0-A12 -> -21.9 | E13: =45+(B13/100)*4 -> 48.18 | F13: =0-A13 -> -23.9 | G13: =45+(B13/100)*4 -> 48.18 | J13: {=IF(ROW(J13)<=COUNTA(D:D)*2,IF(MOD(ROW(J13),2)=1,INDEX(D:D,(ROW(J13)+1)/2),INDEX(F:F,ROW(J13)/2)),"")} -> -9.9 | K13: {=IF(ROW(K13)<=COUNTA(E:E)*2,IF(MOD(ROW(K13),2)=1,INDEX(E:E,(ROW(K13)+1)/2),INDEX(G:G,ROW(K13)/2)),"")} -> 45.88
D14: =0-A13 -> -23.9 | E14: =45+(B14/100)*4 -> 48.5 | F14: =0-A14 -> -25.9 | G14: =45+(B14/100)*4 -> 48.5 | J14: {=IF(ROW(J14)<=COUNTA(D:D)*2,IF(MOD(ROW(J14),2)=1,INDEX(D:D,(ROW(J14)+1)/2),INDEX(F:F,ROW(J14)/2)),"")} -> -11.9 | K14: {=IF(ROW(K14)<=COUNTA(E:E)*2,IF(MOD(ROW(K14),2)=1,INDEX(E:E,(ROW(K14)+1)/2),INDEX(G:G,ROW(K14)/2)),"")} -> 45.88
D15: =0-A14 -> -25.9 | E15: =45+(B15/100)*4 -> 47.94 | F15: =0-A15 -> -27.9 | G15: =45+(B15/100)*4 -> 47.94 | J15: {=IF(ROW(J15)<=COUNTA(D:D)*2,IF(MOD(ROW(J15),2)=1,INDEX(D:D,(ROW(J15)+1)/2),INDEX(F:F,ROW(J15)/2)),"")} -> -11.9 | K15: {=IF(ROW(K15)<=COUNTA(E:E)*2,IF(MOD(ROW(K15),2)=1,INDEX(E:E,(ROW(K15)+1)/2),INDEX(G:G,ROW(K15)/2)),"")} -> 46.46
... D374: =0-A373 -> 0 | E374: =45+(B374/100)*4 -> 45 | F374: =0-A374 -> 0 | G374: =45+(B374/100)*4 -> 45 | J374: {=IF(ROW(J374)<=COUNTA(D:D)*2,IF(MOD(ROW(J374),2)=1,INDEX(D:D,(ROW(J374)+1)/2),INDEX(F:F,ROW(J374)/2)),"")} -> -371.9 | K374: {=IF(ROW(K374)<=COUNTA(E:E)*2,IF(MOD(ROW(K374),2)=1,INDEX(E:E,(ROW(K374)+1)/2),INDEX(G:G,ROW(K374)/2)),"")} -> 46.4
J375: {=IF(ROW(J375)<=COUNTA(D:D)*2,IF(MOD(ROW(J375),2)=1,INDEX(D:D,(ROW(J375)+1)/2),INDEX(F:F,ROW(J375)/2)),"")} -> -371.9 | K375: {=IF(ROW(K375)<=COUNTA(E:E)*2,IF(MOD(ROW(K375),2)=1,INDEX(E:E,(ROW(K375)+1)/2),INDEX(G:G,ROW(K375)/2)),"")} -> 47.14
J376: {=IF(ROW(J376)<=COUNTA(D:D)*2,IF(MOD(ROW(J376),2)=1,INDEX(D:D,(ROW(J376)+1)/2),INDEX(F:F,ROW(J376)/2)),"")} -> -373.9 | K376: {=IF(ROW(K376)<=COUNTA(E:E)*2,IF(MOD(ROW(K376),2)=1,INDEX(E:E,(ROW(K376)+1)/2),INDEX(G:G,ROW(K376)/2)),"")} -> 47.14
J377: {=IF(ROW(J377)<=COUNTA(D:D)*2,IF(MOD(ROW(J377),2)=1,INDEX(D:D,(ROW(J377)+1)/2),INDEX(F:F,ROW(J377)/2)),"")} -> -373.9 | K377: {=IF(ROW(K377)<=COUNTA(E:E)*2,IF(MOD(ROW(K377),2)=1,INDEX(E:E,(ROW(K377)+1)/2),INDEX(G:G,ROW(K377)/2)),"")} -> 47.46
J378: {=IF(ROW(J378)<=COUNTA(D:D)*2,IF(MOD(ROW(J378),2)=1,INDEX(D:D,(ROW(J378)+1)/2),INDEX(F:F,ROW(J378)/2)),"")} -> -375.9 | K378: {=IF(ROW(K378)<=COUNTA(E:E)*2,IF(MOD(ROW(K378),2)=1,INDEX(E:E,(ROW(K378)+1)/2),INDEX(G:G,ROW(K378)/2)),"")} -> 47.46
J379: {=IF(ROW(J379)<=COUNTA(D:D)*2,IF(MOD(ROW(J379),2)=1,INDEX(D:D,(ROW(J379)+1)/2),INDEX(F:F,ROW(J379)/2)),"")} -> -375.9 | K379: {=IF(ROW(K379)<=COUNTA(E:E)*2,IF(MOD(ROW(K379),2)=1,INDEX(E:E,(ROW(K379)+1)/2),INDEX(G:G,ROW(K379)/2)),"")} -> 48.32
J380: {=IF(ROW(J380)<=COUNTA(D:D)*2,IF(MOD(ROW(J380),2)=1,INDEX(D:D,(ROW(J380)+1)/2),INDEX(F:F,ROW(J380)/2)),"")} -> -377.9 | K380: {=IF(ROW(K380)<=COUNTA(E:E)*2,IF(MOD(ROW(K380),2)=1,INDEX(E:E,(ROW(K380)+1)/2),INDEX(G:G,ROW(K380)/2)),"")} -> 48.32
J381: {=IF(ROW(J381)<=COUNTA(D:D)*2,IF(MOD(ROW(J381),2)=1,INDEX(D:D,(ROW(J381)+1)/2),INDEX(F:F,ROW(J381)/2)),"")} -> -377.9 | K381: {=IF(ROW(K381)<=COUNTA(E:E)*2,IF(MOD(ROW(K381),2)=1,INDEX(E:E,(ROW(K381)+1)/2),INDEX(G:G,ROW(K381)/2)),"")} -> 48.44
J382: {=IF(ROW(J382)<=COUNTA(D:D)*2,IF(MOD(ROW(J382),2)=1,INDEX(D:D,(ROW(J382)+1)/2),INDEX(F:F,ROW(J382)/2)),"")} -> -379.9 | K382: {=IF(ROW(K382)<=COUNTA(E:E)*2,IF(MOD(ROW(K382),2)=1,INDEX(E:E,(ROW(K382)+1)/2),INDEX(G:G,ROW(K382)/2)),"")} -> 48.44
J383: {=IF(ROW(J383)<=COUNTA(D:D)*2,IF(MOD(ROW(J383),2)=1,INDEX(D:D,(ROW(J383)+1)/2),INDEX(F:F,ROW(J383)/2)),"")} -> -379.9 | K383: {=IF(ROW(K383)<=COUNTA(E:E)*2,IF(MOD(ROW(K383),2)=1,INDEX(E:E,(ROW(K383)+1)/2),INDEX(G:G,ROW(K383)/2)),"")} -> 48.36
J384: {=IF(ROW(J384)<=COUNTA(D:D)*2,IF(MOD(ROW(J384),2)=1,INDEX(D:D,(ROW(J384)+1)/2),INDEX(F:F,ROW(J384)/2)),"")} -> -381.9 | K384: {=IF(ROW(K384)<=COUNTA(E:E)*2,IF(MOD(ROW(K384),2)=1,INDEX(E:E,(ROW(K384)+1)/2),INDEX(G:G,ROW(K384)/2)),"")} -> 48.36
J385: {=IF(ROW(J385)<=COUNTA(D:D)*2,IF(MOD(ROW(J385),2)=1,INDEX(D:D,(ROW(J385)+1)/2),INDEX(F:F,ROW(J385)/2)),"")} -> -381.9 | K385: {=IF(ROW(K385)<=COUNTA(E:E)*2,IF(MOD(ROW(K385),2)=1,INDEX(E:E,(ROW(K385)+1)/2),INDEX(G:G,ROW(K385)/2)),"")} -> 48.26
J386: {=IF(ROW(J386)<=COUNTA(D:D)*2,IF(MOD(ROW(J386),2)=1,INDEX(D:D,(ROW(J386)+1)/2),INDEX(F:F,ROW(J386)/2)),"")} -> -383.9 | K386: {=IF(ROW(K386)<=COUNTA(E:E)*2,IF(MOD(ROW(K386),2)=1,INDEX(E:E,(ROW(K386)+1)/2),INDEX(G:G,ROW(K386)/2)),"")} -> 48.26
... J744: {=IF(ROW(J744)<=COUNTA(D:D)*2,IF(MOD(ROW(J744),2)=1,INDEX(D:D,(ROW(J744)+1)/2),INDEX(F:F,ROW(J744)/2)),"")} -> 0 | K744: {=IF(ROW(K744)<=COUNTA(E:E)*2,IF(MOD(ROW(K744),2)=1,INDEX(E:E,(ROW(K744)+1)/2),INDEX(G:G,ROW(K744)/2)),"")} -> 45

Sheet 冲洗液投图
D1: x1 | E1: y1 | F1: x2 | G1: y2 | J1: {=IF(ROW(J1)<=COUNTA(D:D)*2,IF(MOD(ROW(J1),2)=1,INDEX(D:D,(ROW(J1)+1)/2),INDEX(F:F,ROW(J1)/2)),"")} -> x1 | K1: {=IF(ROW(K1)<=COUNTA(E:E)*2,IF(MOD(ROW(K1),2)=1,INDEX(E:E,(ROW(K1)+1)/2),INDEX(G:G,ROW(K1)/2)),"")} -> y1
D2: =0 -> 0 | E2: =49+(B2)*4 -> 49.23272 | F2: =0-A2 -> -1.9 | G2: =49+(B2)*4 -> 49.23272 | J2: {=IF(ROW(J2)<=COUNTA(D:D)*2,IF(MOD(ROW(J2),2)=1,INDEX(D:D,(ROW(J2)+1)/2),INDEX(F:F,ROW(J2)/2)),"")} -> x2 | K2: {=IF(ROW(K2)<=COUNTA(E:E)*2,IF(MOD(ROW(K2),2)=1,INDEX(E:E,(ROW(K2)+1)/2),INDEX(G:G,ROW(K2)/2)),"")} -> y2
D3: =0-A2 -> -1.9 | E3: =49+(B3)*4 -> 49.23624 | F3: =0-A3 -> -3.9 | G3: =49+(B3)*4 -> 49.23624 | J3: {=IF(ROW(J3)<=COUNTA(D:D)*2,IF(MOD(ROW(J3),2)=1,INDEX(D:D,(ROW(J3)+1)/2),INDEX(F:F,ROW(J3)/2)),"")} -> 0 | K3: {=IF(ROW(K3)<=COUNTA(E:E)*2,IF(MOD(ROW(K3),2)=1,INDEX(E:E,(ROW(K3)+1)/2),INDEX(G:G,ROW(K3)/2)),"")} -> 49.23272
D4: =0-A3 -> -3.9 | E4: =49+(B4)*4 -> 49.46364 | F4: =0-A4 -> -5.9 | G4: =49+(B4)*4 -> 49.46364 | J4: {=IF(ROW(J4)<=COUNTA(D:D)*2,IF(MOD(ROW(J4),2)=1,INDEX(D:D,(ROW(J4)+1)/2),INDEX(F:F,ROW(J4)/2)),"")} -> -1.9 | K4: {=IF(ROW(K4)<=COUNTA(E:E)*2,IF(MOD(ROW(K4),2)=1,INDEX(E:E,(ROW(K4)+1)/2),INDEX(G:G,ROW(K4)/2)),"")} -> 49.23272
D5: =0-A4 -> -5.9 | E5: =49+(B5)*4 -> 49.47344 | F5: =0-A5 -> -7.9 | G5: =49+(B5)*4 -> 49.47344 | J5: {=IF(ROW(J5)<=COUNTA(D:D)*2,IF(MOD(ROW(J5),2)=1,INDEX(D:D,(ROW(J5)+1)/2),INDEX(F:F,ROW(J5)/2)),"")} -> -1.9 | K5: {=IF(ROW(K5)<=COUNTA(E:E)*2,IF(MOD(ROW(K5),2)=1,INDEX(E:E,(ROW(K5)+1)/2),INDEX(G:G,ROW(K5)/2)),"")} -> 49.23624
D6: =0-A5 -> -7.9 | E6: =49+(B6)*4 -> 49.32976 | F6: =0-A6 -> -9.9 | G6: =49+(B6)*4 -> 49.32976 | J6: {=IF(ROW(J6)<=COUNTA(D:D)*2,IF(MOD(ROW(J6),2)=1,INDEX(D:D,(ROW(J6)+1)/2),INDEX(F:F,ROW(J6)/2)),"")} -> -3.9 | K6: {=IF(ROW(K6)<=COUNTA(E:E)*2,IF(MOD(ROW(K6),2)=1,INDEX(E:E,(ROW(K6)+1)/2),INDEX(G:G,ROW(K6)/2)),"")} -> 49.23624
D7: =0-A6 -> -9.9 | E7: =49+(B7)*4 -> 49.48632 | F7: =0-A7 -> -11.9 | G7: =49+(B7)*4 -> 49.48632 | J7: {=IF(ROW(J7)<=COUNTA(D:D)*2,IF(MOD(ROW(J7),2)=1,INDEX(D:D,(ROW(J7)+1)/2),INDEX(F:F,ROW(J7)/2)),"")} -> -3.9 | K7: {=IF(ROW(K7)<=COUNTA(E:E)*2,IF(MOD(ROW(K7),2)=1,INDEX(E:E,(ROW(K7)+1)/2),INDEX(G:G,ROW(K7)/2)),"")} -> 49.46364
D8: =0-A7 -> -11.9 | E8: =49+(B8)*4 -> 49.338 | F8: =0-A8 -> -13.9 | G8: =49+(B8)*4 -> 49.338 | J8: {=IF(ROW(J8)<=COUNTA(D:D)*2,IF(MOD(ROW(J8),2)=1,INDEX(D:D,(ROW(J8)+1)/2),INDEX(F:F,ROW(J8)/2)),"")} -> -5.9 | K8: {=IF(ROW(K8)<=COUNTA(E:E)*2,IF(MOD(ROW(K8),2)=1,INDEX(E:E,(ROW(K8)+1)/2),INDEX(G:G,ROW(K8)/2)),"")} -> 49.46364
D9: =0-A8 -> -13.9 | E9: =49+(B9)*4 -> 49.32864 | F9: =0-A9 -> -15.9 | G9: =49+(B9)*4 -> 49.32864 | J9: {=IF(ROW(J9)<=COUNTA(D:D)*2,IF(MOD(ROW(J9),2)=1,INDEX(D:D,(ROW(J9)+1)/2),INDEX(F:F,ROW(J9)/2)),"")} -> -5.9 | K9: {=IF(ROW(K9)<=COUNTA(E:E)*2,IF(MOD(ROW(K9),2)=1,INDEX(E:E,(ROW(K9)+1)/2),INDEX(G:G,ROW(K9)/2)),"")} -> 49.47344
D10: =0-A9 -> -15.9 | E10: =49+(B10)*4 -> 49.33696 | F10: =0-A10 -> -17.9 | G10: =49+(B10)*4 -> 49.33696 | J10: {=IF(ROW(J10)<=COUNTA(D:D)*2,IF(MOD(ROW(J10),2)=1,INDEX(D:D,(ROW(J10)+1)/2),INDEX(F:F,ROW(J10)/2)),"")} -> -7.9 | K10: {=IF(ROW(K10)<=COUNTA(E:E)*2,IF(MOD(ROW(K10),2)=1,INDEX(E:E,(ROW(K10)+1)/2),INDEX(G:G,ROW(K10)/2)),"")} -> 49.47344
D11: =0-A10 -> -17.9 | E11: =49+(B11)*4 -> 49.26496 | F11: =0-A11 -> -19.9 | G11: =49+(B11)*4 -> 49.26496 | J11: {=IF(ROW(J11)<=COUNTA(D:D)*2,IF(MOD(ROW(J11),2)=1,INDEX(D:D,(ROW(J11)+1)/2),INDEX(F:F,ROW(J11)/2)),"")} -> -7.9 | K11: {=IF(ROW(K11)<=COUNTA(E:E)*2,IF(MOD(ROW(K11),2)=1,INDEX(E:E,(ROW(K11)+1)/2),INDEX(G:G,ROW(K11)/2)),"")} -> 49.32976
D12: =0-A11 -> -19.9 | E12: =49+(B12)*4 -> 49.34448 | F12: =0-A12 -> -21.9 | G12: =49+(B12)*4 -> 49.34448 | J12: {=IF(ROW(J12)<=COUNTA(D:D)*2,IF(MOD(ROW(J12),2)=1,INDEX(D:D,(ROW(J12)+1)/2),INDEX(F:F,ROW(J12)/2)),"")} -> -9.9 | K12: {=IF(ROW(K12)<=COUNTA(E:E)*2,IF(MOD(ROW(K12),2)=1,INDEX(E:E,(ROW(K12)+1)/2),INDEX(G:G,ROW(K12)/2)),"")} -> 49.32976
D13: =0-A12 -> -21.9 | E13: =49+(B13)*4 -> 49.354 | F13: =0-A13 -> -23.9 | G13: =49+(B13)*4 -> 49.354 | J13: {=IF(ROW(J13)<=COUNTA(D:D)*2,IF(MOD(ROW(J13),2)=1,INDEX(D:D,(ROW(J13)+1)/2),INDEX(F:F,ROW(J13)/2)),"")} -> -9.9 | K13: {=IF(ROW(K13)<=COUNTA(E:E)*2,IF(MOD(ROW(K13),2)=1,INDEX(E:E,(ROW(K13)+1)/2),INDEX(G:G,ROW(K13)/2)),"")} -> 49.48632
D14: =0-A13 -> -23.9 | E14: =49+(B14)*4 -> 49.48532 | F14: =0-A14 -> -25.9 | G14: =49+(B14)*4 -> 49.48532 | J14: {=IF(ROW(J14)<=COUNTA(D:D)*2,IF(MOD(ROW(J14),2)=1,INDEX(D:D,(ROW(J14)+1)/2),INDEX(F:F,ROW(J14)/2)),"")} -> -11.9 | K14: {=IF(ROW(K14)<=COUNTA(E:E)*2,IF(MOD(ROW(K14),2)=1,INDEX(E:E,(ROW(K14)+1)/2),INDEX(G:G,ROW(K14)/2)),"")} -> 49.48632
... D387: =0-A386 -> 0 | E387: =49+(B387)*4 -> 49 | F387: =0-A387 -> 0 | G387: =49+(B387)*4 -> 49 | J387: {=IF(ROW(J387)<=COUNTA(D:D)*2,IF(MOD(ROW(J387),2)=1,INDEX(D:D,(ROW(J387)+1)/2),INDEX(F:F,ROW(J387)/2)),"")} -> -383.9 | K387: {=IF(ROW(K387)<=COUNTA(E:E)*2,IF(MOD(ROW(K387),2)=1,INDEX(E:E,(ROW(K387)+1)/2),INDEX(G:G,ROW(K387)/2)),"")} -> 51
J388: {=IF(ROW(J388)<=COUNTA(D:D)*2,IF(MOD(ROW(J388),2)=1,INDEX(D:D,(ROW(J388)+1)/2),INDEX(F:F,ROW(J388)/2)),"")} -> -385.9 | K388: {=IF(ROW(K388)<=COUNTA(E:E)*2,IF(MOD(ROW(K388),2)=1,INDEX(E:E,(ROW(K388)+1)/2),INDEX(G:G,ROW(K388)/2)),"")} -> 51
J389: {=IF(ROW(J389)<=COUNTA(D:D)*2,IF(MOD(ROW(J389),2)=1,INDEX(D:D,(ROW(J389)+1)/2),INDEX(F:F,ROW(J389)/2)),"")} -> -385.9 | K389: {=IF(ROW(K389)<=COUNTA(E:E)*2,IF(MOD(ROW(K389),2)=1,INDEX(E:E,(ROW(K389)+1)/2),INDEX(G:G,ROW(K389)/2)),"")} -> 50.32
J390: {=IF(ROW(J390)<=COUNTA(D:D)*2,IF(MOD(ROW(J390),2)=1,INDEX(D:D,(ROW(J390)+1)/2),INDEX(F:F,ROW(J390)/2)),"")} -> -387.9 | K390: {=IF(ROW(K390)<=COUNTA(E:E)*2,IF(MOD(ROW(K390),2)=1,INDEX(E:E,(ROW(K390)+1)/2),INDEX(G:G,ROW(K390)/2)),"")} -> 50.32
J391: {=IF(ROW(J391)<=COUNTA(D:D)*2,IF(MOD(ROW(J391),2)=1,INDEX(D:D,(ROW(J391)+1)/2),INDEX(F:F,ROW(J391)/2)),"")} -> -387.9 | K391: {=IF(ROW(K391)<=COUNTA(E:E)*2,IF(MOD(ROW(K391),2)=1,INDEX(E:E,(ROW(K391)+1)/2),INDEX(G:G,ROW(K391)/2)),"")} -> 51.04
J392: {=IF(ROW(J392)<=COUNTA(D:D)*2,IF(MOD(ROW(J392),2)=1,INDEX(D:D,(ROW(J392)+1)/2),INDEX(F:F,ROW(J392)/2)),"")} -> -389.9 | K392: {=IF(ROW(K392)<=COUNTA(E:E)*2,IF(MOD(ROW(K392),2)=1,INDEX(E:E,(ROW(K392)+1)/2),INDEX(G:G,ROW(K392)/2)),"")} -> 51.04
J393: {=IF(ROW(J393)<=COUNTA(D:D)*2,IF(MOD(ROW(J393),2)=1,INDEX(D:D,(ROW(J393)+1)/2),INDEX(F:F,ROW(J393)/2)),"")} -> -389.9 | K393: {=IF(ROW(K393)<=COUNTA(E:E)*2,IF(MOD(ROW(K393),2)=1,INDEX(E:E,(ROW(K393)+1)/2),INDEX(G:G,ROW(K393)/2)),"")} -> 51.04
J394: {=IF(ROW(J394)<=COUNTA(D:D)*2,IF(MOD(ROW(J394),2)=1,INDEX(D:D,(ROW(J394)+1)/2),INDEX(F:F,ROW(J394)/2)),"")} -> -391.9 | K394: {=IF(ROW(K394)<=COUNTA(E:E)*2,IF(MOD(ROW(K394),2)=1,INDEX(E:E,(ROW(K394)+1)/2),INDEX(G:G,ROW(K394)/2)),"")} -> 51.04
J395: {=IF(ROW(J395)<=COUNTA(D:D)*2,IF(MOD(ROW(J395),2)=1,INDEX(D:D,(ROW(J395)+1)/2),INDEX(F:F,ROW(J395)/2)),"")} -> -391.9 | K395: {=IF(ROW(K395)<=COUNTA(E:E)*2,IF(MOD(ROW(K395),2)=1,INDEX(E:E,(ROW(K395)+1)/2),INDEX(G:G,ROW(K395)/2)),"")} -> 51.08
J396: {=IF(ROW(J396)<=COUNTA(D:D)*2,IF(MOD(ROW(J396),2)=1,INDEX(D:D,(ROW(J396)+1)/2),INDEX(F:F,ROW(J396)/2)),"")} -> -393.9 | K396: {=IF(ROW(K396)<=COUNTA(E:E)*2,IF(MOD(ROW(K396),2)=1,INDEX(E:E,(ROW(K396)+1)/2),INDEX(G:G,ROW(K396)/2)),"")} -> 51.08
J397: {=IF(ROW(J397)<=COUNTA(D:D)*2,IF(MOD(ROW(J397),2)=1,INDEX(D:D,(ROW(J397)+1)/2),INDEX(F:F,ROW(J397)/2)),"")} -> -393.9 | K397: {=IF(ROW(K397)<=COUNTA(E:E)*2,IF(MOD(ROW(K397),2)=1,INDEX(E:E,(ROW(K397)+1)/2),INDEX(G:G,ROW(K397)/2)),"")} -> 51.08
J398: {=IF(ROW(J398)<=COUNTA(D:D)*2,IF(MOD(ROW(J398),2)=1,INDEX(D:D,(ROW(J398)+1)/2),INDEX(F:F,ROW(J398)/2)),"")} -> -395.9 | K398: {=IF(ROW(K398)<=COUNTA(E:E)*2,IF(MOD(ROW(K398),2)=1,INDEX(E:E,(ROW(K398)+1)/2),INDEX(G:G,ROW(K398)/2)),"")} -> 51.08
J399: {=IF(ROW(J399)<=COUNTA(D:D)*2,IF(MOD(ROW(J399),2)=1,INDEX(D:D,(ROW(J399)+1)/2),INDEX(F:F,ROW(J399)/2)),"")} -> -395.9 | K399: {=IF(ROW(K399)<=COUNTA(E:E)*2,IF(MOD(ROW(K399),2)=1,INDEX(E:E,(ROW(K399)+1)/2),INDEX(G:G,ROW(K399)/2)),"")} -> 51.08
... J756: {=IF(ROW(J756)<=COUNTA(D:D)*2,IF(MOD(ROW(J756),2)=1,INDEX(D:D,(ROW(J756)+1)/2),INDEX(F:F,ROW(J756)/2)),"")} -> 0 | K756: {=IF(ROW(K756)<=COUNTA(E:E)*2,IF(MOD(ROW(K756),2)=1,INDEX(E:E,(ROW(K756)+1)/2),INDEX(G:G,ROW(K756)/2)),"")} -> 49

Sheet 水位变幅投图
A1: 起 | B1: 止 | C1: 起钻后 | D1: 下钻前
F2: =IF(IF(A2<>"",0-A2,0-B1)=0,"",IF(A2<>"",0-A2,0-B1))
F3: =IF(IF(A3<>"",0-A3,0-B2)=0,"",IF(A3<>"",0-A3,0-B2)) -> -1.9 | I3: 水位变幅折线坐标
F4: =IF(IF(A4<>"",0-A4,0-B3)=0,"",IF(A4<>"",0-A4,0-B3)) -> -3.9 | G4: =IF(((C3-D3)<>"")*(D3<>""),55+(C3-D3)/5*2,"") -> 54.944
F5: =IF(IF(A5<>"",0-A5,0-B4)=0,"",IF(A5<>"",0-A5,0-B4)) -> -5.9 | G5: =IF(((C4-D4)<>"")*(D4<>""),55+(C4-D4)/5*2,"") | I5: {=_xlfn._xlws.FILTER(F:F,(F:F<>"")*(G:G<>""))} -> -3.9 | J5: {=_xlfn._xlws.FILTER(G:G,(F:F<>"")*(G:G<>""))} -> 54.944
F6: =IF(IF(A6<>"",0-A6,0-B5)=0,"",IF(A6<>"",0-A6,0-B5)) -> -7.9 | G6: =IF(((C5-D5)<>"")*(D5<>""),55+(C5-D5)/5*2,"") | I6: -9.9 | J6: 54.912
F7: =IF(IF(A7<>"",0-A7,0-B6)=0,"",IF(A7<>"",0-A7,0-B6)) -> -9.9 | G7: =IF(((C6-D6)<>"")*(D6<>""),55+(C6-D6)/5*2,"") -> 54.912 | I7: -11.9 | J7: 54.856
F8: =IF(IF(A8<>"",0-A8,0-B7)=0,"",IF(A8<>"",0-A8,0-B7)) -> -11.9 | G8: =IF(((C7-D7)<>"")*(D7<>""),55+(C7-D7)/5*2,"") -> 54.856 | I8: -21.9 | J8: 54.892
F9: =IF(IF(A9<>"",0-A9,0-B8)=0,"",IF(A9<>"",0-A9,0-B8)) -> -13.9 | G9: =IF(((C8-D8)<>"")*(D8<>""),55+(C8-D8)/5*2,"") | I9: -27.9 | J9: 54.828
F10: =IF(IF(A10<>"",0-A10,0-B9)=0,"",IF(A10<>"",0-A10,0-B9)) -> -15.9 | G10: =IF(((C9-D9)<>"")*(D9<>""),55+(C9-D9)/5*2,"") | I10: -35.9 | J10: 54.872
F11: =IF(IF(A11<>"",0-A11,0-B10)=0,"",IF(A11<>"",0-A11,0-B10)) -> -17.9 | G11: =IF(((C10-D10)<>"")*(D10<>""),55+(C10-D10)/5*2,"") | I11: -43.9 | J11: 54.864
F12: =IF(IF(A12<>"",0-A12,0-B11)=0,"",IF(A12<>"",0-A12,0-B11)) -> -19.9 | G12: =IF(((C11-D11)<>"")*(D11<>""),55+(C11-D11)/5*2,"") | I12: -77.9 | J12: 54.86
F13: =IF(IF(A13<>"",0-A13,0-B12)=0,"",IF(A13<>"",0-A13,0-B12)) -> -21.9 | G13: =IF(((C12-D12)<>"")*(D12<>""),55+(C12-D12)/5*2,"") -> 54.892 | I13: -87.9 | J13: 54.864
F14: =IF(IF(A14<>"",0-A14,0-B13)=0,"",IF(A14<>"",0-A14,0-B13)) -> -23.9 | G14: =IF(((C13-D13)<>"")*(D13<>""),55+(C13-D13)/5*2,"") | I14: -101.9 | J14: 54.828
F15: =IF(IF(A15<>"",0-A15,0-B14)=0,"",IF(A15<>"",0-A15,0-B14)) -> -25.9 | G15: =IF(((C14-D14)<>"")*(D14<>""),55+(C14-D14)/5*2,"") | I15: -109.9 | J15: 54.824
F16: =IF(IF(A16<>"",0-A16,0-B15)=0,"",IF(A16<>"",0-A16,0-B15)) -> -27.9 | G16: =IF(((C15-D15)<>"")*(D15<>""),55+(C15-D15)/5*2,"") -> 54.828 | I16: -119.9 | J16: 54.9
F17: =IF(IF(A17<>"",0-A17,0-B16)=0,"",IF(A17<>"",0-A17,0-B16)) -> -29.9 | G17: =IF(((C16-D16)<>"")*(D16<>""),55+(C16-D16)/5*2,"") | I17: -129.9 | J17: 54.868
... F38: =IF(IF(A38<>"",0-A38,0-B37)=0,"",IF(A38<>"",0-A38,0-B37)) -> -71.9 | G38: =IF(((C37-D37)<>"")*(D37<>""),55+(C37-D37)/5*2,"") | I38: -291.9 | J38: 54.912
F39: =IF(IF(A39<>"",0-A39,0-B38)=0,"",IF(A39<>"",0-A39,0-B38)) -> -73.9 | I39: -299.9 | J39: 54.88
F40: =IF(IF(A40<>"",0-A40,0-B39)=0,"",IF(A40<>"",0-A40,0-B39)) -> -75.9 | G40: =IF(((C39-D39)<>"")*(D39<>""),55+(C39-D39)/5*2,"") | I40: -309.9 | J40: 54.864
F41: =IF(IF(A41<>"",0-A41,0-B40)=0,"",IF(A41<>"",0-A41,0-B40)) -> -77.9 | G41: =IF(((C40-D40)<>"")*(D40<>""),55+(C40-D40)/5*2,"") -> 54.86 | I41: -319.9 | J41: 54.872
F42: =IF(IF(A42<>"",0-A42,0-B41)=0,"",IF(A42<>"",0-A42,0-B41)) -> -79.9 | G42: =IF(((C41-D41)<>"")*(D41<>""),55+(C41-D41)/5*2,"") | I42: -329.9 | J42: 54.844
F43: =IF(IF(A43<>"",0-A43,0-B42)=0,"",IF(A43<>"",0-A43,0-B42)) -> -81.9 | G43: =IF(((C42-D42)<>"")*(D42<>""),55+(C42-D42)/5*2,"") | I43: -337.9 | J43: 54.872
F44: =IF(IF(A44<>"",0-A44,0-B43)=0,"",IF(A44<>"",0-A44,0-B43)) -> -83.9 | G44: =IF(((C43-D43)<>"")*(D43<>""),55+(C43-D43)/5*2,"") | I44: -345.9 | J44: 54.832
F45: =IF(IF(A45<>"",0-A45,0-B44)=0,"",IF(A45<>"",0-A45,0-B44)) -> -85.9 | G45: =IF(((C44-D44)<>"")*(D44<>""),55+(C44-D44)/5*2,"") | I45: -355.9 | J45: 54.908
F46: =IF(IF(A46<>"",0-A46,0-B45)=0,"",IF(A46<>"",0-A46,0-B45)) -> -87.9 | G46: =IF(((C45-D45)<>"")*(D45<>""),55+(C45-D45)/5*2,"") -> 54.864 | I46: -359.9 | J46: 54.832
F47: =IF(IF(A47<>"",0-A47,0-B46)=0,"",IF(A47<>"",0-A47,0-B46)) -> -89.9 | G47: =IF(((C46-D46)<>"")*(D46<>""),55+(C46-D46)/5*2,"") | I47: -363.9 | J47: 54.864
F48: =IF(IF(A48<>"",0-A48,0-B47)=0,"",IF(A48<>"",0-A48,0-B47)) -> -91.9 | G48: =IF(((C47-D47)<>"")*(D47<>""),55+(C47-D47)/5*2,"") | I48: -369.9 | J48: 54.868
F49: =IF(IF(A49<>"",0-A49,0-B48)=0,"",IF(A49<>"",0-A49,0-B48)) -> -93.9 | G49: =IF(((C48-D48)<>"")*(D48<>""),55+(C48-D48)/5*2,"") | I49: -371.9 | J49: 54.804
F50: =IF(IF(A50<>"",0-A50,0-B49)=0,"",IF(A50<>"",0-A50,0-B49)) -> -95.9 | G50: =IF(((C49-D49)<>"")*(D49<>""),55+(C49-D49)/5*2,"") | I50: -381.9 | J50: 54.876
F51: =IF(IF(A51<>"",0-A51,0-B50)=0,"",IF(A51<>"",0-A51,0-B50)) -> -97.9 | G51: =IF(((C50-D50)<>"")*(D50<>""),55+(C50-D50)/5*2,"") | I51: -393.9 | J51: 54.872
... F101: =IF(IF(A101<>"",0-A101,0-B100)=0,"",IF(A101<>"",0-A101,0-B100)) -> -197.9 | G101: =IF(((C100-D100)<>"")*(D100<>""),55+(C100-D100)/5*2,"") | I101: -677.9 | J101: 54.82
F102: =IF(IF(A102<>"",0-A102,0-B101)=0,"",IF(A102<>"",0-A102,0-B101)) -> -199.9 | G102: =IF(((C101-D101)<>"")*(D101<>""),55+(C101-D101)/5*2,"")
F103: =IF(IF(A103<>"",0-A103,0-B102)=0,"",IF(A103<>"",0-A103,0-B102)) -> -201.9 | G103: =IF(((C102-D102)<>"")*(D102<>""),55+(C102-D102)/5*2,"") -> 54.864
F104: =IF(IF(A104<>"",0-A104,0-B103)=0,"",IF(A104<>"",0-A104,0-B103)) -> -203.9 | G104: =IF(((C103-D103)<>"")*(D103<>""),55+(C103-D103)/5*2,"")
F105: =IF(IF(A105<>"",0-A105,0-B104)=0,"",IF(A105<>"",0-A105,0-B104)) -> -205.9 | G105: =IF(((C104-D104)<>"")*(D104<>""),55+(C104-D104)/5*2,"")
F106: =IF(IF(A106<>"",0-A106,0-B105)=0,"",IF(A106<>"",0-A106,0-B105)) -> -207.9 | G106: =IF(((C105-D105)<>"")*(D105<>""),55+(C105-D105)/5*2,"") -> 54.896
F107: =IF(IF(A107<>"",0-A107,0-B106)=0,"",IF(A107<>"",0-A107,0-B106)) -> -209.9 | G107: =IF(((C106-D106)<>"")*(D106<>""),55+(C106-D106)/5*2,"")
F108: =IF(IF(A108<>"",0-A108,0-B107)=0,"",IF(A108<>"",0-A108,0-B107)) -> -211.9 | G108: =IF(((C107-D107)<>"")*(D107<>""),55+(C107-D107)/5*2,"")
F109: =IF(IF(A109<>"",0-A109,0-B108)=0,"",IF(A109<>"",0-A109,0-B108)) -> -213.9 | G109: =IF(((C108-D108)<>"")*(D108<>""),55+(C108-D108)/5*2,"")
...

Sheet 其他投图
A1: 含水段上下界孔深及厚度 | E1: 软弱段及及厚度 | I1: 静止水位 | L1: 钻孔结构 | Q1: 含水段文字坐标(标注0以上坐标) | T1: 软弱段文字坐标(标注0以上坐标)
A3: 深度 | B3: 坐标 | D3: 含水层厚度 | E3: 深度 | F3: 坐标 | H3: 软弱段厚度 | I3: 深度 | J3: 坐标 | L3: 自 | M3: 至 | N3: 孔径（mm） | O3: 坐标 | Q3: 标注 | R3: 坐标 | T3: 标注 | U3: 坐标
B4: {=-INDEX(A:A,ROUNDUP(ROW(A8)/2,0))} -> 0 | C4: 61 | D4: =IF(A5<>"",A5-0,"") | F4: {=-INDEX(E:E,ROUNDUP(ROW(E7)/2,0))} -> 0 | G4: 65 | H4: =E5 -> 0 | J4: {=-INDEX(I:I,ROUNDUP(ROW(I7)/2,0))} -> -32.91 | K4: 65 | O4: {=-INDEX(N:N,ROUNDUP(ROW(N8)/2,0))} -> 0 | P4: =70-2*N5/120 -> 68.75 | Q4: {=IF(MOD(ROW()-8,4)=0,"",IF(MOD(ROW()-8,4)=1,INDEX(A:A,7+INT((ROW()-8)/4)*2)-INDEX(A:A,6+INT((ROW()-8)/4)*2),IF(MOD(ROW()-8,4)=2,INDEX(A:A,7+INT((ROW()-8)/4)*2),INDEX(A:A,8+INT((ROW()-8)/4)*2))))} | R4: =B4 -> 0 | S4: =C4 -> 61 | T4: {=IF(MOD(ROW()-8,4)=0,"",IF(MOD(ROW()-8,4)=1,INDEX(E:E,7+INT((ROW()-8)/4)*2)-INDEX(E:E,6+INT((ROW()-8)/4)*2),IF(MOD(ROW()-8,4)=2,INDEX(E:E,7+INT((ROW()-8)/4)*2),INDEX(E:E,8+INT((ROW()-8)/4)*2))))} | U4: =F4 -> 0 | V4: =G4 -> 65
B5: {=-INDEX(A:A,ROUNDUP(ROW(A9)/2,0))} -> 0 | C5: 61 | F5: {=-INDEX(E:E,ROUNDUP(ROW(E9)/2,0))} -> 0 | G5: 65 | J5: {=-INDEX(I:I,ROUNDUP(ROW(I8)/2,0))} -> -32.91 | K5: 68 | L5: 0 | M5: 6 | N5: 75 | O5: {=-INDEX(M:M,ROUNDUP(ROW(M9)/2,0))} -> -6 | P5: =70-2*N5/120 -> 68.75 | Q5: {=IF(MOD(ROW()-8,4)=0,"",IF(MOD(ROW()-8,4)=1,INDEX(A:A,7+INT((ROW()-8)/4)*2)-INDEX(A:A,6+INT((ROW()-8)/4)*2),IF(MOD(ROW()-8,4)=2,INDEX(A:A,7+INT((ROW()-8)/4)*2),INDEX(A:A,8+INT((ROW()-8)/4)*2))))} -> 0 | R5: =IF(R6<R4,(R6+R4)/2-0.3,0) -> 0 | S5: =C5-IF(LEN(TEXT(Q5,"0"))=1,2.51,IF(LEN(TEXT(Q5,"0"))=2,2.62,2.82)) -> 58.49 | T5: {=IF(MOD(ROW()-8,4)=0,"",IF(MOD(ROW()-8,4)=1,INDEX(E:E,7+INT((ROW()-8)/4)*2)-INDEX(E:E,6+INT((ROW()-8)/4)*2),IF(MOD(ROW()-8,4)=2,INDEX(E:E,7+INT((ROW()-8)/4)*2),INDEX(E:E,8+INT((ROW()-8)/4)*2))))} -> 0 | U5: =IF(U6<U4,(U6+U4)/2-0.3,0) -> 0 | V5: =G5-IF(LEN(TEXT(T5,"0"))=1,2.53,IF(LEN(TEXT(T5,"0"))=2,2.65,2.85)) -> 62.47
B6: {=-INDEX(A:A,ROUNDUP(ROW(A10)/2,0))} -> 0 | C6: 57 | D6: =IF(A7<>"",A7-A6,"") -> 29.04 | F6: {=-INDEX(E:E,ROUNDUP(ROW(E10)/2,0))} -> 0 | G6: 61 | H6: =IF(E7<>"",E7-E6,"") -> 2.1 | O6: {=IF(OR(L6=0,L6="",M6=0,M6="",N6=0,N6=""),"",-INDEX(M:M,ROUNDUP(ROW(M10)/2,0)))} | P6: =IF(OR(L6=0,L6="",M6=0,M6="",N6=0,N6=""),"",70-2*N6/120) | Q6: {=IF(MOD(ROW()-8,4)=0,"",IF(MOD(ROW()-8,4)=1,INDEX(A:A,7+INT((ROW()-8)/4)*2)-INDEX(A:A,6+INT((ROW()-8)/4)*2),IF(MOD(ROW()-8,4)=2,INDEX(A:A,7+INT((ROW()-8)/4)*2),INDEX(A:A,8+INT((ROW()-8)/4)*2))))} -> 0 | R6: =B6 -> 0 | S6: =C6-IF(LEN(TEXT(Q6,"0"))=1,0.5,IF(LEN(TEXT(Q6,"0"))=2,0.61,0.81)) -> 56.5 | T6: {=IF(MOD(ROW()-8,4)=0,"",IF(MOD(ROW()-8,4)=1,INDEX(E:E,7+INT((ROW()-8)/4)*2)-INDEX(E:E,6+INT((ROW()-8)/4)*2),IF(MOD(ROW()-8,4)=2,INDEX(E:E,7+INT((ROW()-8)/4)*2),INDEX(E:E,8+INT((ROW()-8)/4)*2))))} -> 0 | U6: =F6 -> 0 | V6: =G6-IF(LEN(TEXT(T6,"0"))=1,0.5,IF(LEN(TEXT(T6,"0"))=2,0.61,0.81)) -> 60.5
B7: {=-INDEX(A:A,ROUNDUP(ROW(A11)/2,0))} -> -32.91 | C7: 57 | F7: {=-INDEX(E:E,ROUNDUP(ROW(E11)/2,0))} -> 0 | G7: 61 | J7: =-I4 -> -32.91 | K7: 66.5 | O7: {=IF(OR(L6=0,L6="",M6=0,M6="",N6=0,N6=""),"",-INDEX(M:M,ROUNDUP(ROW(M11)/2,0)))} | P7: =IF(OR(L6=0,L6="",M6=0,M6="",N6=0,N6=""),"",70-2*N6/120) | Q7: {=IF(MOD(ROW()-8,4)=0,"",IF(MOD(ROW()-8,4)=1,INDEX(A:A,7+INT((ROW()-8)/4)*2)-INDEX(A:A,6+INT((ROW()-8)/4)*2),IF(MOD(ROW()-8,4)=2,INDEX(A:A,7+INT((ROW()-8)/4)*2),INDEX(A:A,8+INT((ROW()-8)/4)*2))))} -> 32.91 | R7: =B7-0.6 -> -33.51 | S7: =C7-IF(LEN(TEXT(Q7,"0"))=1,0.5,IF(LEN(TEXT(Q7,"0"))=2,0.61,0.81)) -> 56.39 | T7: {=IF(MOD(ROW()-8,4)=0,"",IF(MOD(ROW()-8,4)=1,INDEX(E:E,7+INT((ROW()-8)/4)*2)-INDEX(E:E,6+INT((ROW()-8)/4)*2),IF(MOD(ROW()-8,4)=2,INDEX(E:E,7+INT((ROW()-8)/4)*2),INDEX(E:E,8+INT((ROW()-8)/4)*2))))} -> 0 | U7: =F7-0.6 -> -0.6 | V7: =G7-IF(LEN(TEXT(T7,"0"))=1,0.5,IF(LEN(TEXT(T7,"0"))=2,0.61,0.81)) -> 60.5
B8: {=-INDEX(A:A,ROUNDUP(ROW(A12)/2,0))} -> -32.91 | C8: 61 | D8: =IF(A9<>"",A9-A8,"") -> 21.92 | F8: {=-INDEX(E:E,ROUNDUP(ROW(E12)/2,0))} -> 0 | G8: 65 | H8: =IF(E9<>"",E9-E8,"") -> 1.07 | J8: =-(I4-0.5) -> -32.41 | K8: 66 | O8: =O7 | P8: =IF(OR(L6=0,L6="",M6=0,M6="",N6=0,N6=""),"",70+70-P7) | Q8: {=IF(MOD(ROW()-8,4)=0,"",IF(MOD(ROW()-8,4)=1,INDEX(A:A,7+INT((ROW()-8)/4)*2)-INDEX(A:A,6+INT((ROW()-8)/4)*2),IF(MOD(ROW()-8,4)=2,INDEX(A:A,7+INT((ROW()-8)/4)*2),INDEX(A:A,8+INT((ROW()-8)/4)*2))))} | R8: =B8 -> -32.91 | S8: =C8 -> 61 | T8: {=IF(MOD(ROW()-8,4)=0,"",IF(MOD(ROW()-8,4)=1,INDEX(E:E,7+INT((ROW()-8)/4)*2)-INDEX(E:E,6+INT((ROW()-8)/4)*2),IF(MOD(ROW()-8,4)=2,INDEX(E:E,7+INT((ROW()-8)/4)*2),INDEX(E:E,8+INT((ROW()-8)/4)*2))))} | U8: =F8 -> 0 | V8: =G8 -> 65
B9: {=-INDEX(A:A,ROUNDUP(ROW(A13)/2,0))} -> -61.95 | C9: 61 | F9: {=-INDEX(E:E,ROUNDUP(ROW(E13)/2,0))} -> -2.1 | G9: 65 | J9: =-(I4-0.5) -> -32.41 | K9: 67 | O9: =O6 | P9: =IF(OR(L6=0,L6="",M6=0,M6="",N6=0,N6=""),"",70+70-P6) | Q9: {=IF(MOD(ROW()-8,4)=0,"",IF(MOD(ROW()-8,4)=1,INDEX(A:A,7+INT((ROW()-8)/4)*2)-INDEX(A:A,6+INT((ROW()-8)/4)*2),IF(MOD(ROW()-8,4)=2,INDEX(A:A,7+INT((ROW()-8)/4)*2),INDEX(A:A,8+INT((ROW()-8)/4)*2))))} -> 29.04 | R9: =IF(R10<R8,(R10+R8)/2-0.3,0) -> -47.73 | S9: =C9-IF(LEN(TEXT(Q9,"0"))=1,2.51,IF(LEN(TEXT(Q9,"0"))=2,2.62,2.82)) -> 58.38 | T9: {=IF(MOD(ROW()-8,4)=0,"",IF(MOD(ROW()-8,4)=1,INDEX(E:E,7+INT((ROW()-8)/4)*2)-INDEX(E:E,6+INT((ROW()-8)/4)*2),IF(MOD(ROW()-8,4)=2,INDEX(E:E,7+INT((ROW()-8)/4)*2),INDEX(E:E,8+INT((ROW()-8)/4)*2))))} -> 2.1 | U9: =IF(U10<U8,(U10+U8)/2-0.3,0) -> -1.35 | V9: =G9-IF(LEN(TEXT(T9,"0"))=1,2.53,IF(LEN(TEXT(T9,"0"))=2,2.65,2.85)) -> 62.47
B10: {=-INDEX(A:A,ROUNDUP(ROW(A14)/2,0))} -> -61.95 | C10: 57 | D10: =IF(A11<>"",A11-A10,"") | F10: {=-INDEX(E:E,ROUNDUP(ROW(E14)/2,0))} -> -2.1 | G10: 61 | H10: =IF(E11<>"",E11-E10,"") -> 0.55 | J10: =J7 -> -32.91 | K10: =K7 -> 66.5 | O10: =O5 -> -6 | P10: =70+70-P5 -> 71.25 | Q10: {=IF(MOD(ROW()-8,4)=0,"",IF(MOD(ROW()-8,4)=1,INDEX(A:A,7+INT((ROW()-8)/4)*2)-INDEX(A:A,6+INT((ROW()-8)/4)*2),IF(MOD(ROW()-8,4)=2,INDEX(A:A,7+INT((ROW()-8)/4)*2),INDEX(A:A,8+INT((ROW()-8)/4)*2))))} -> 61.95 | R10: =B10 -> -61.95 | S10: =C10-IF(LEN(TEXT(Q10,"0"))=1,0.5,IF(LEN(TEXT(Q10,"0"))=2,0.61,0.81)) -> 56.39 | T10: {=IF(MOD(ROW()-8,4)=0,"",IF(MOD(ROW()-8,4)=1,INDEX(E:E,7+INT((ROW()-8)/4)*2)-INDEX(E:E,6+INT((ROW()-8)/4)*2),IF(MOD(ROW()-8,4)=2,INDEX(E:E,7+INT((ROW()-8)/4)*2),INDEX(E:E,8+INT((ROW()-8)/4)*2))))} -> 2.1 | U10: =F10 -> -2.1 | V10: =G10-IF(LEN(TEXT(T10,"0"))=1,0.5,IF(LEN(TEXT(T10,"0"))=2,0.61,0.81)) -> 60.5
B11: {=-INDEX(A:A,ROUNDUP(ROW(A15)/2,0))} -> -550.16 | C11: 57 | F11: {=-INDEX(E:E,ROUNDUP(ROW(E15)/2,0))} -> -120.98 | G11: 61 | O11: =O4 -> 0 | P11: =70+70-P4 -> 71.25 | Q11: {=IF(MOD(ROW()-8,4)=0,"",IF(MOD(ROW()-8,4)=1,INDEX(A:A,7+INT((ROW()-8)/4)*2)-INDEX(A:A,6+INT((ROW()-8)/4)*2),IF(MOD(ROW()-8,4)=2,INDEX(A:A,7+INT((ROW()-8)/4)*2),INDEX(A:A,8+INT((ROW()-8)/4)*2))))} -> 550.16 | R11: =B11-0.6 -> -550.76 | S11: =C11-IF(LEN(TEXT(Q11,"0"))=1,0.5,IF(LEN(TEXT(Q11,"0"))=2,0.61,0.81)) -> 56.19 | T11: {=IF(MOD(ROW()-8,4)=0,"",IF(MOD(ROW()-8,4)=1,INDEX(E:E,7+INT((ROW()-8)/4)*2)-INDEX(E:E,6+INT((ROW()-8)/4)*2),IF(MOD(ROW()-8,4)=2,INDEX(E:E,7+INT((ROW()-8)/4)*2),INDEX(E:E,8+INT((ROW()-8)/4)*2))))} -> 120.98 | U11: =F11-0.6 -> -121.58 | V11: =G11-IF(LEN(TEXT(T11,"0"))=1,0.5,IF(LEN(TEXT(T11,"0"))=2,0.61,0.81)) -> 60.19
B12: {=-INDEX(A:A,ROUNDUP(ROW(A16)/2,0))} -> -550.16 | C12: 61 | D12: =IF(A13<>"",A13-A12,"") | F12: {=-INDEX(E:E,ROUNDUP(ROW(E16)/2,0))} -> -120.98 | G12: 65 | H12: =IF(E13<>"",E13-E12,"") -> 2.5 | J12: =-(I4+0.2) -> -33.11 | K12: 66.2 | Q12: {=IF(MOD(ROW()-8,4)=0,"",IF(MOD(ROW()-8,4)=1,INDEX(A:A,7+INT((ROW()-8)/4)*2)-INDEX(A:A,6+INT((ROW()-8)/4)*2),IF(MOD(ROW()-8,4)=2,INDEX(A:A,7+INT((ROW()-8)/4)*2),INDEX(A:A,8+INT((ROW()-8)/4)*2))))} | R12: =B12 -> -550.16 | S12: =C12 -> 61 | T12: {=IF(MOD(ROW()-8,4)=0,"",IF(MOD(ROW()-8,4)=1,INDEX(E:E,7+INT((ROW()-8)/4)*2)-INDEX(E:E,6+INT((ROW()-8)/4)*2),IF(MOD(ROW()-8,4)=2,INDEX(E:E,7+INT((ROW()-8)/4)*2),INDEX(E:E,8+INT((ROW()-8)/4)*2))))} | U12: =F12 -> -120.98 | V12: =G12 -> 65
B13: {=-INDEX(A:A,ROUNDUP(ROW(A17)/2,0))} -> -572.08 | C13: 61 | F13: {=-INDEX(E:E,ROUNDUP(ROW(E17)/2,0))} -> -122.05 | G13: 65 | J13: =-(I4+0.2) -> -33.11 | K13: 66.8 | Q13: {=IF(MOD(ROW()-8,4)=0,"",IF(MOD(ROW()-8,4)=1,INDEX(A:A,7+INT((ROW()-8)/4)*2)-INDEX(A:A,6+INT((ROW()-8)/4)*2),IF(MOD(ROW()-8,4)=2,INDEX(A:A,7+INT((ROW()-8)/4)*2),INDEX(A:A,8+INT((ROW()-8)/4)*2))))} -> 21.92 | R13: =IF(R14<R12,(R14+R12)/2-0.3,0) -> -561.42 | S13: =C13-IF(LEN(TEXT(Q13,"0"))=1,2.51,IF(LEN(TEXT(Q13,"0"))=2,2.62,2.82)) -> 58.38 | T13: {=IF(MOD(ROW()-8,4)=0,"",IF(MOD(ROW()-8,4)=1,INDEX(E:E,7+INT((ROW()-8)/4)*2)-INDEX(E:E,6+INT((ROW()-8)/4)*2),IF(MOD(ROW()-8,4)=2,INDEX(E:E,7+INT((ROW()-8)/4)*2),INDEX(E:E,8+INT((ROW()-8)/4)*2))))} -> 1.07 | U13: =IF(U14<U12,(U14+U12)/2-0.3,0) -> -121.815 | V13: =G13-IF(LEN(TEXT(T13,"0"))=1,2.53,IF(LEN(TEXT(T13,"0"))=2,2.65,2.85)) -> 62.47
B14: {=-INDEX(A:A,ROUNDUP(ROW(A18)/2,0))} -> -572.08 | C14: 57 | D14: =IF(A15<>"",A15-A14,"") | F14: {=-INDEX(E:E,ROUNDUP(ROW(E18)/2,0))} -> -122.05 | G14: 61 | H14: =IF(E15<>"",E15-E14,"") -> 4.5 | Q14: {=IF(MOD(ROW()-8,4)=0,"",IF(MOD(ROW()-8,4)=1,INDEX(A:A,7+INT((ROW()-8)/4)*2)-INDEX(A:A,6+INT((ROW()-8)/4)*2),IF(MOD(ROW()-8,4)=2,INDEX(A:A,7+INT((ROW()-8)/4)*2),INDEX(A:A,8+INT((ROW()-8)/4)*2))))} -> 572.08 | R14: =B14 -> -572.08 | S14: =C14-IF(LEN(TEXT(Q14,"0"))=1,0.5,IF(LEN(TEXT(Q14,"0"))=2,0.61,0.81)) -> 56.19 | T14: {=IF(MOD(ROW()-8,4)=0,"",IF(MOD(ROW()-8,4)=1,INDEX(E:E,7+INT((ROW()-8)/4)*2)-INDEX(E:E,6+INT((ROW()-8)/4)*2),IF(MOD(ROW()-8,4)=2,INDEX(E:E,7+INT((ROW()-8)/4)*2),INDEX(E:E,8+INT((ROW()-8)/4)*2))))} -> 122.05 | U14: =F14 -> -122.05 | V14: =G14-IF(LEN(TEXT(T14,"0"))=1,0.5,IF(LEN(TEXT(T14,"0"))=2,0.61,0.81)) -> 60.19
B15: {=-INDEX(A:A,ROUNDUP(ROW(A19)/2,0))} -> 0 | C15: 57 | F15: {=-INDEX(E:E,ROUNDUP(ROW(E19)/2,0))} -> -423.25 | G15: 61 | J15: =-(I4+0.4) -> -33.31 | K15: 66.3 | Q15: {=IF(MOD(ROW()-8,4)=0,"",IF(MOD(ROW()-8,4)=1,INDEX(A:A,7+INT((ROW()-8)/4)*2)-INDEX(A:A,6+INT((ROW()-8)/4)*2),IF(MOD(ROW()-8,4)=2,INDEX(A:A,7+INT((ROW()-8)/4)*2),INDEX(A:A,8+INT((ROW()-8)/4)*2))))} -> 0 | R15: =B15-0.6 -> -0.6 | S15: =C15-IF(LEN(TEXT(Q15,"0"))=1,0.5,IF(LEN(TEXT(Q15,"0"))=2,0.61,0.81)) -> 56.5 | T15: {=IF(MOD(ROW()-8,4)=0,"",IF(MOD(ROW()-8,4)=1,INDEX(E:E,7+INT((ROW()-8)/4)*2)-INDEX(E:E,6+INT((ROW()-8)/4)*2),IF(MOD(ROW()-8,4)=2,INDEX(E:E,7+INT((ROW()-8)/4)*2),INDEX(E:E,8+INT((ROW()-8)/4)*2))))} -> 423.25 | U15: =F15-0.6 -> -423.85 | V15: =G15-IF(LEN(TEXT(T15,"0"))=1,0.5,IF(LEN(TEXT(T15,"0"))=2,0.61,0.81)) -> 60.19
B16: {=-INDEX(A:A,ROUNDUP(ROW(A20)/2,0))} -> 0 | C16: 61 | D16: =IF(A17<>"",A17-A16,"") | F16: {=-INDEX(E:E,ROUNDUP(ROW(E20)/2,0))} -> -423.25 | G16: 65 | H16: =IF(E17<>"",E17-E16,"") -> 1.2 | J16: =-(I4+0.4) -> -33.31 | K16: 66.7 | Q16: {=IF(MOD(ROW()-8,4)=0,"",IF(MOD(ROW()-8,4)=1,INDEX(A:A,7+INT((ROW()-8)/4)*2)-INDEX(A:A,6+INT((ROW()-8)/4)*2),IF(MOD(ROW()-8,4)=2,INDEX(A:A,7+INT((ROW()-8)/4)*2),INDEX(A:A,8+INT((ROW()-8)/4)*2))))} | R16: =B16 -> 0 | S16: =C16 -> 61 | T16: {=IF(MOD(ROW()-8,4)=0,"",IF(MOD(ROW()-8,4)=1,INDEX(E:E,7+INT((ROW()-8)/4)*2)-INDEX(E:E,6+INT((ROW()-8)/4)*2),IF(MOD(ROW()-8,4)=2,INDEX(E:E,7+INT((ROW()-8)/4)*2),INDEX(E:E,8+INT((ROW()-8)/4)*2))))} | U16: =F16 -> -423.25 | V16: =G16 -> 65
B17: {=-INDEX(A:A,ROUNDUP(ROW(A21)/2,0))} -> 0 | C17: 61 | F17: {=-INDEX(E:E,ROUNDUP(ROW(E21)/2,0))} -> -423.8 | G17: 65 | I17: 静止文字坐标 | Q17: {=IF(MOD(ROW()-8,4)=0,"",IF(MOD(ROW()-8,4)=1,INDEX(A:A,7+INT((ROW()-8)/4)*2)-INDEX(A:A,6+INT((ROW()-8)/4)*2),IF(MOD(ROW()-8,4)=2,INDEX(A:A,7+INT((ROW()-8)/4)*2),INDEX(A:A,8+INT((ROW()-8)/4)*2))))} -> 0 | R17: =IF(R18<R16,(R18+R16)/2-0.3,0) -> 0 | S17: =C17-IF(LEN(TEXT(Q17,"0"))=1,2.51,IF(LEN(TEXT(Q17,"0"))=2,2.62,2.82)) -> 58.49 | T17: {=IF(MOD(ROW()-8,4)=0,"",IF(MOD(ROW()-8,4)=1,INDEX(E:E,7+INT((ROW()-8)/4)*2)-INDEX(E:E,6+INT((ROW()-8)/4)*2),IF(MOD(ROW()-8,4)=2,INDEX(E:E,7+INT((ROW()-8)/4)*2),INDEX(E:E,8+INT((ROW()-8)/4)*2))))} -> 0.55 | U17: =IF(U18<U16,(U18+U16)/2-0.3,0) -> -423.825 | V17: =G17-IF(LEN(TEXT(T17,"0"))=1,2.53,IF(LEN(TEXT(T17,"0"))=2,2.65,2.85)) -> 62.47
B18: {=-INDEX(A:A,ROUNDUP(ROW(A22)/2,0))} -> 0 | C18: 57 | D18: =IF(A19<>"",A19-A18,"") | F18: {=-INDEX(E:E,ROUNDUP(ROW(E22)/2,0))} -> -423.8 | G18: 61 | H18: =IF(E19<>"",E19-E18,"") -> 0.8 | Q18: {=IF(MOD(ROW()-8,4)=0,"",IF(MOD(ROW()-8,4)=1,INDEX(A:A,7+INT((ROW()-8)/4)*2)-INDEX(A:A,6+INT((ROW()-8)/4)*2),IF(MOD(ROW()-8,4)=2,INDEX(A:A,7+INT((ROW()-8)/4)*2),INDEX(A:A,8+INT((ROW()-8)/4)*2))))} -> 0 | R18: =B18 -> 0 | S18: =C18-IF(LEN(TEXT(Q18,"0"))=1,0.5,IF(LEN(TEXT(Q18,"0"))=2,0.61,0.81)) -> 56.5 | T18: {=IF(MOD(ROW()-8,4)=0,"",IF(MOD(ROW()-8,4)=1,INDEX(E:E,7+INT((ROW()-8)/4)*2)-INDEX(E:E,6+INT((ROW()-8)/4)*2),IF(MOD(ROW()-8,4)=2,INDEX(E:E,7+INT((ROW()-8)/4)*2),INDEX(E:E,8+INT((ROW()-8)/4)*2))))} -> 423.8 | U18: =F18 -> -423.8 | V18: =G18-IF(LEN(TEXT(T18,"0"))=1,0.5,IF(LEN(TEXT(T18,"0"))=2,0.61,0.81)) -> 60.19
B19: {=-INDEX(A:A,ROUNDUP(ROW(A23)/2,0))} -> 0 | C19: 57 | F19: {=-INDEX(E:E,ROUNDUP(ROW(E23)/2,0))} -> -511.9 | G19: 61 | I19: 标注 | J19: 坐标 | Q19: {=IF(MOD(ROW()-8,4)=0,"",IF(MOD(ROW()-8,4)=1,INDEX(A:A,7+INT((ROW()-8)/4)*2)-INDEX(A:A,6+INT((ROW()-8)/4)*2),IF(MOD(ROW()-8,4)=2,INDEX(A:A,7+INT((ROW()-8)/4)*2),INDEX(A:A,8+INT((ROW()-8)/4)*2))))} -> 0 | R19: =B19-0.6 -> -0.6 | S19: =C19-IF(LEN(TEXT(Q19,"0"))=1,0.5,IF(LEN(TEXT(Q19,"0"))=2,0.61,0.81)) -> 56.5 | T19: {=IF(MOD(ROW()-8,4)=0,"",IF(MOD(ROW()-8,4)=1,INDEX(E:E,7+INT((ROW()-8)/4)*2)-INDEX(E:E,6+INT((ROW()-8)/4)*2),IF(MOD(ROW()-8,4)=2,INDEX(E:E,7+INT((ROW()-8)/4)*2),INDEX(E:E,8+INT((ROW()-8)/4)*2))))} -> 511.9 | U19: =F19-0.6 -> -512.5 | V19: =G19-IF(LEN(TEXT(T19,"0"))=1,0.5,IF(LEN(TEXT(T19,"0"))=2,0.61,0.81)) -> 60.19
B20: {=-INDEX(A:A,ROUNDUP(ROW(A24)/2,0))} -> 0 | C20: 61 | D20: =IF(A21<>"",A21-A20,"") | F20: {=-INDEX(E:E,ROUNDUP(ROW(E24)/2,0))} -> -511.9 | G20: 65 | H20: =IF(E21<>"",E21-E20,"") | I20: =IF(I4<>"",(TEXT(I4,"0.00")&"m"),"") -> 32.91m | J20: =-(I4+1.1) -> -34.01 | K20: =65-IF(LEN(TEXT(I4,"0"))=1,0.25,IF(LEN(TEXT(I4,"0"))=2,0.35,0.55)) -> 64.65 | Q20: {=IF(MOD(ROW()-8,4)=0,"",IF(MOD(ROW()-8,4)=1,INDEX(A:A,7+INT((ROW()-8)/4)*2)-INDEX(A:A,6+INT((ROW()-8)/4)*2),IF(MOD(ROW()-8,4)=2,INDEX(A:A,7+INT((ROW()-8)/4)*2),INDEX(A:A,8+INT((ROW()-8)/4)*2))))} | R20: =B20 -> 0 | S20: =C20 -> 61 | T20: {=IF(MOD(ROW()-8,4)=0,"",IF(MOD(ROW()-8,4)=1,INDEX(E:E,7+INT((ROW()-8)/4)*2)-INDEX(E:E,6+INT((ROW()-8)/4)*2),IF(MOD(ROW()-8,4)=2,INDEX(E:E,7+INT((ROW()-8)/4)*2),INDEX(E:E,8+INT((ROW()-8)/4)*2))))} | U20: =F20 -> -511.9 | V20: =G20 -> 65
B21: {=-INDEX(A:A,ROUNDUP(ROW(A25)/2,0))} -> 0 | C21: 61 | F21: {=-INDEX(E:E,ROUNDUP(ROW(E25)/2,0))} -> -514.4 | G21: 65 | J21: =-I4 -> -32.91 | K21: 57 | Q21: {=IF(MOD(ROW()-8,4)=0,"",IF(MOD(ROW()-8,4)=1,INDEX(A:A,7+INT((ROW()-8)/4)*2)-INDEX(A:A,6+INT((ROW()-8)/4)*2),IF(MOD(ROW()-8,4)=2,INDEX(A:A,7+INT((ROW()-8)/4)*2),INDEX(A:A,8+INT((ROW()-8)/4)*2))))} -> 0 | R21: =IF(R22<R20,(R22+R20)/2-0.3,0) -> 0 | S21: =C21-IF(LEN(TEXT(Q21,"0"))=1,2.51,IF(LEN(TEXT(Q21,"0"))=2,2.62,2.82)) -> 58.49 | T21: {=IF(MOD(ROW()-8,4)=0,"",IF(MOD(ROW()-8,4)=1,INDEX(E:E,7+INT((ROW()-8)/4)*2)-INDEX(E:E,6+INT((ROW()-8)/4)*2),IF(MOD(ROW()-8,4)=2,INDEX(E:E,7+INT((ROW()-8)/4)*2),INDEX(E:E,8+INT((ROW()-8)/4)*2))))} -> 2.5 | U21: =IF(U22<U20,(U22+U20)/2-0.3,0) -> -513.45 | V21: =G21-IF(LEN(TEXT(T21,"0"))=1,2.53,IF(LEN(TEXT(T21,"0"))=2,2.65,2.85)) -> 62.47
B22: {=-INDEX(A:A,ROUNDUP(ROW(A26)/2,0))} -> 0 | C22: 57 | D22: =IF(A23<>"",A23-A22,"") | F22: {=-INDEX(E:E,ROUNDUP(ROW(E26)/2,0))} -> -514.4 | G22: 61 | H22: =IF(E23<>"",E23-E22,"") | J22: =-I4 -> -32.91 | K22: 61 | Q22: {=IF(MOD(ROW()-8,4)=0,"",IF(MOD(ROW()-8,4)=1,INDEX(A:A,7+INT((ROW()-8)/4)*2)-INDEX(A:A,6+INT((ROW()-8)/4)*2),IF(MOD(ROW()-8,4)=2,INDEX(A:A,7+INT((ROW()-8)/4)*2),INDEX(A:A,8+INT((ROW()-8)/4)*2))))} -> 0 | R22: =B22 -> 0 | S22: =C22-IF(LEN(TEXT(Q22,"0"))=1,0.5,IF(LEN(TEXT(Q22,"0"))=2,0.61,0.81)) -> 56.5 | T22: {=IF(MOD(ROW()-8,4)=0,"",IF(MOD(ROW()-8,4)=1,INDEX(E:E,7+INT((ROW()-8)/4)*2)-INDEX(E:E,6+INT((ROW()-8)/4)*2),IF(MOD(ROW()-8,4)=2,INDEX(E:E,7+INT((ROW()-8)/4)*2),INDEX(E:E,8+INT((ROW()-8)/4)*2))))} -> 514.4 | U22: =F22 -> -514.4 | V22: =G22-IF(LEN(TEXT(T22,"0"))=1,0.5,IF(LEN(TEXT(T22,"0"))=2,0.61,0.81)) -> 60.19
B23: {=-INDEX(A:A,ROUNDUP(ROW(A27)/2,0))} -> 0 | C23: 57 | F23: {=-INDEX(E:E,ROUNDUP(ROW(E27)/2,0))} -> -563.9 | G23: 61 | I23: =IF(I4<>"",(TEXT(I4,"0.00")),"") -> 32.91 | J23: =-I23-0.6 -> -33.51 | K23: 56.5 | Q23: {=IF(MOD(ROW()-8,4)=0,"",IF(MOD(ROW()-8,4)=1,INDEX(A:A,7+INT((ROW()-8)/4)*2)-INDEX(A:A,6+INT((ROW()-8)/4)*2),IF(MOD(ROW()-8,4)=2,INDEX(A:A,7+INT((ROW()-8)/4)*2),INDEX(A:A,8+INT((ROW()-8)/4)*2))))} -> 0 | R23: =B23-0.6 -> -0.6 | S23: =C23-IF(LEN(TEXT(Q23,"0"))=1,0.5,IF(LEN(TEXT(Q23,"0"))=2,0.61,0.81)) -> 56.5 | T23: {=IF(MOD(ROW()-8,4)=0,"",IF(MOD(ROW()-8,4)=1,INDEX(E:E,7+INT((ROW()-8)/4)*2)-INDEX(E:E,6+INT((ROW()-8)/4)*2),IF(MOD(ROW()-8,4)=2,INDEX(E:E,7+INT((ROW()-8)/4)*2),INDEX(E:E,8+INT((ROW()-8)/4)*2))))} -> 563.9 | U23: =F23-0.6 -> -564.5 | V23: =G23-IF(LEN(TEXT(T23,"0"))=1,0.5,IF(LEN(TEXT(T23,"0"))=2,0.61,0.81)) -> 60.19
B24: {=-INDEX(A:A,ROUNDUP(ROW(A28)/2,0))} -> 0 | C24: 61 | D24: =IF(A25<>"",A25-A24,"") | F24: {=-INDEX(E:E,ROUNDUP(ROW(E28)/2,0))} -> -563.9 | G24: 65 | H24: =IF(E25<>"",E25-E24,"") | I24: =A5-I4 -> -32.91 | J24: =-(A5+I4)/2-0.3 -> -16.755 | K24: =57-IF(LEN(TEXT(I24,"0"))=1,0.5,IF(LEN(TEXT(I24,"0"))=2,0.61,0.81)) -> 56.19 | Q24: {=IF(MOD(ROW()-8,4)=0,"",IF(MOD(ROW()-8,4)=1,INDEX(A:A,7+INT((ROW()-8)/4)*2)-INDEX(A:A,6+INT((ROW()-8)/4)*2),IF(MOD(ROW()-8,4)=2,INDEX(A:A,7+INT((ROW()-8)/4)*2),INDEX(A:A,8+INT((ROW()-8)/4)*2))))} | R24: =B24 -> 0 | S24: =C24 -> 61 | T24: {=IF(MOD(ROW()-8,4)=0,"",IF(MOD(ROW()-8,4)=1,INDEX(E:E,7+INT((ROW()-8)/4)*2)-INDEX(E:E,6+INT((ROW()-8)/4)*2),IF(MOD(ROW()-8,4)=2,INDEX(E:E,7+INT((ROW()-8)/4)*2),INDEX(E:E,8+INT((ROW()-8)/4)*2))))} | U24: =F24 -> -563.9 | V24: =G24 -> 65
B25: {=-INDEX(A:A,ROUNDUP(ROW(A29)/2,0))} -> 0 | C25: 61 | F25: {=-INDEX(E:E,ROUNDUP(ROW(E29)/2,0))} -> -568.4 | G25: 65 | Q25: {=IF(MOD(ROW()-8,4)=0,"",IF(MOD(ROW()-8,4)=1,INDEX(A:A,7+INT((ROW()-8)/4)*2)-INDEX(A:A,6+INT((ROW()-8)/4)*2),IF(MOD(ROW()-8,4)=2,INDEX(A:A,7+INT((ROW()-8)/4)*2),INDEX(A:A,8+INT((ROW()-8)/4)*2))))} -> 0 | R25: =IF(R26<R24,(R26+R24)/2-0.3,0) -> 0 | S25: =C25-IF(LEN(TEXT(Q25,"0"))=1,2.51,IF(LEN(TEXT(Q25,"0"))=2,2.62,2.82)) -> 58.49 | T25: {=IF(MOD(ROW()-8,4)=0,"",IF(MOD(ROW()-8,4)=1,INDEX(E:E,7+INT((ROW()-8)/4)*2)-INDEX(E:E,6+INT((ROW()-8)/4)*2),IF(MOD(ROW()-8,4)=2,INDEX(E:E,7+INT((ROW()-8)/4)*2),INDEX(E:E,8+INT((ROW()-8)/4)*2))))} -> 4.5 | U25: =IF(U26<U24,(U26+U24)/2-0.3,0) -> -566.45 | V25: =G25-IF(LEN(TEXT(T25,"0"))=1,2.53,IF(LEN(TEXT(T25,"0"))=2,2.65,2.85)) -> 62.47
B26: {=-INDEX(A:A,ROUNDUP(ROW(A30)/2,0))} -> 0 | C26: 57 | D26: =IF(A27<>"",A27-A26,"") | F26: {=-INDEX(E:E,ROUNDUP(ROW(E30)/2,0))} -> -568.4 | G26: 61 | H26: =IF(E27<>"",E27-E26,"") | Q26: {=IF(MOD(ROW()-8,4)=0,"",IF(MOD(ROW()-8,4)=1,INDEX(A:A,7+INT((ROW()-8)/4)*2)-INDEX(A:A,6+INT((ROW()-8)/4)*2),IF(MOD(ROW()-8,4)=2,INDEX(A:A,7+INT((ROW()-8)/4)*2),INDEX(A:A,8+INT((ROW()-8)/4)*2))))} -> 0 | R26: =B26 -> 0 | S26: =C26-IF(LEN(TEXT(Q26,"0"))=1,0.5,IF(LEN(TEXT(Q26,"0"))=2,0.61,0.81)) -> 56.5 | T26: {=IF(MOD(ROW()-8,4)=0,"",IF(MOD(ROW()-8,4)=1,INDEX(E:E,7+INT((ROW()-8)/4)*2)-INDEX(E:E,6+INT((ROW()-8)/4)*2),IF(MOD(ROW()-8,4)=2,INDEX(E:E,7+INT((ROW()-8)/4)*2),INDEX(E:E,8+INT((ROW()-8)/4)*2))))} -> 568.4 | U26: =F26 -> -568.4 | V26: =G26-IF(LEN(TEXT(T26,"0"))=1,0.5,IF(LEN(TEXT(T26,"0"))=2,0.61,0.81)) -> 60.19
B27: {=-INDEX(A:A,ROUNDUP(ROW(A31)/2,0))} -> 0 | C27: 57 | F27: {=-INDEX(E:E,ROUNDUP(ROW(E31)/2,0))} -> -648.7 | G27: 61 | Q27: {=IF(MOD(ROW()-8,4)=0,"",IF(MOD(ROW()-8,4)=1,INDEX(A:A,7+INT((ROW()-8)/4)*2)-INDEX(A:A,6+INT((ROW()-8)/4)*2),IF(MOD(ROW()-8,4)=2,INDEX(A:A,7+INT((ROW()-8)/4)*2),INDEX(A:A,8+INT((ROW()-8)/4)*2))))} -> 0 | R27: =B27-0.6 -> -0.6 | S27: =C27-IF(LEN(TEXT(Q27,"0"))=1,0.5,IF(LEN(TEXT(Q27,"0"))=2,0.61,0.81)) -> 56.5 | T27: {=IF(MOD(ROW()-8,4)=0,"",IF(MOD(ROW()-8,4)=1,INDEX(E:E,7+INT((ROW()-8)/4)*2)-INDEX(E:E,6+INT((ROW()-8)/4)*2),IF(MOD(ROW()-8,4)=2,INDEX(E:E,7+INT((ROW()-8)/4)*2),INDEX(E:E,8+INT((ROW()-8)/4)*2))))} -> 648.7 | U27: =F27-0.6 -> -649.3 | V27: =G27-IF(LEN(TEXT(T27,"0"))=1,0.5,IF(LEN(TEXT(T27,"0"))=2,0.61,0.81)) -> 60.19
B28: {=-INDEX(A:A,ROUNDUP(ROW(A32)/2,0))} -> 0 | C28: 61 | D28: =IF(A29<>"",A29-A28,"") | F28: {=-INDEX(E:E,ROUNDUP(ROW(E32)/2,0))} -> -648.7 | G28: 65 | Q28: {=IF(MOD(ROW()-8,4)=0,"",IF(MOD(ROW()-8,4)=1,INDEX(A:A,7+INT((ROW()-8)/4)*2)-INDEX(A:A,6+INT((ROW()-8)/4)*2),IF(MOD(ROW()-8,4)=2,INDEX(A:A,7+INT((ROW()-8)/4)*2),INDEX(A:A,8+INT((ROW()-8)/4)*2))))} | R28: =B28 -> 0 | S28: =C28 -> 61 | T28: {=IF(MOD(ROW()-8,4)=0,"",IF(MOD(ROW()-8,4)=1,INDEX(E:E,7+INT((ROW()-8)/4)*2)-INDEX(E:E,6+INT((ROW()-8)/4)*2),IF(MOD(ROW()-8,4)=2,INDEX(E:E,7+INT((ROW()-8)/4)*2),INDEX(E:E,8+INT((ROW()-8)/4)*2))))} | U28: =F28 -> -648.7 | V28: =G28 -> 65
B29: {=-INDEX(A:A,ROUNDUP(ROW(A33)/2,0))} -> 0 | C29: 61 | F29: {=-INDEX(E:E,ROUNDUP(ROW(E33)/2,0))} -> -649.9 | G29: 65 | Q29: {=IF(MOD(ROW()-8,4)=0,"",IF(MOD(ROW()-8,4)=1,INDEX(A:A,7+INT((ROW()-8)/4)*2)-INDEX(A:A,6+INT((ROW()-8)/4)*2),IF(MOD(ROW()-8,4)=2,INDEX(A:A,7+INT((ROW()-8)/4)*2),INDEX(A:A,8+INT((ROW()-8)/4)*2))))} -> 0 | R29: =IF(R30<R28,(R30+R28)/2-0.3,0) -> 0 | S29: =C29-IF(LEN(TEXT(Q29,"0"))=1,2.51,IF(LEN(TEXT(Q29,"0"))=2,2.62,2.82)) -> 58.49 | T29: {=IF(MOD(ROW()-8,4)=0,"",IF(MOD(ROW()-8,4)=1,INDEX(E:E,7+INT((ROW()-8)/4)*2)-INDEX(E:E,6+INT((ROW()-8)/4)*2),IF(MOD(ROW()-8,4)=2,INDEX(E:E,7+INT((ROW()-8)/4)*2),INDEX(E:E,8+INT((ROW()-8)/4)*2))))} -> 1.2 | U29: =IF(U30<U28,(U30+U28)/2-0.3,0) -> -649.6 | V29: =G29-IF(LEN(TEXT(T29,"0"))=1,2.53,IF(LEN(TEXT(T29,"0"))=2,2.65,2.85)) -> 62.47
B30: {=-INDEX(A:A,ROUNDUP(ROW(A34)/2,0))} -> 0 | C30: 57 | D30: =IF(A31<>"",A31-A30,"") | F30: {=-INDEX(E:E,ROUNDUP(ROW(E34)/2,0))} -> -649.9 | G30: 61 | Q30: {=IF(MOD(ROW()-8,4)=0,"",IF(MOD(ROW()-8,4)=1,INDEX(A:A,7+INT((ROW()-8)/4)*2)-INDEX(A:A,6+INT((ROW()-8)/4)*2),IF(MOD(ROW()-8,4)=2,INDEX(A:A,7+INT((ROW()-8)/4)*2),INDEX(A:A,8+INT((ROW()-8)/4)*2))))} -> 0 | R30: =B30 -> 0 | S30: =C30-IF(LEN(TEXT(Q30,"0"))=1,0.5,IF(LEN(TEXT(Q30,"0"))=2,0.61,0.81)) -> 56.5 | T30: {=IF(MOD(ROW()-8,4)=0,"",IF(MOD(ROW()-8,4)=1,INDEX(E:E,7+INT((ROW()-8)/4)*2)-INDEX(E:E,6+INT((ROW()-8)/4)*2),IF(MOD(ROW()-8,4)=2,INDEX(E:E,7+INT((ROW()-8)/4)*2),INDEX(E:E,8+INT((ROW()-8)/4)*2))))} -> 649.9 | U30: =F30 -> -649.9 | V30: =G30-IF(LEN(TEXT(T30,"0"))=1,0.5,IF(LEN(TEXT(T30,"0"))=2,0.61,0.81)) -> 60.19
